Workbook
Name BS: Statements!$B$55
Name CF: Statements!$B$103
Name days: Dashboard!$G$18
Name Debt: Schedule!$B$86
Name EF: Assumptions!$B$83
Name Equity: Schedule!$B$112
Name IS: Statements!$B$20
Name PPE: Schedule!$B$13
Name RE: Schedule!$B$112
Name RF: Assumptions!$B$18
Name tax_rate: FCFF!$E$14
Name terminal_growth: FCFF!$E$16
Name wacc: FCFF!$E$15
Name WC: Schedule!$B$63

Sheet Dashboard
B2: Denny's Diner
B3: Dashboard
B4: (In $ thousands, except per share amounts)
B7: Model Assumption | F7: Units:
B9: Company Name | G9: =B2 -> Denny's Diner | M9: Cell Reference
B10: Ticker | G10: DENN
B11: Last Historical | F11: Date | G11: =Statements!I7 -> 45651 | L11: Hardcode | N11: Caution
L12: Calculation | N12: Assumptions
B13: Selected Scenario | G13: Street | L13: Reference | N13: Notes
L14: (Except for the dashboard, and others)
B15: Model Start Date | F15: Date | G15: =Statements!I7 -> 45651
B16: Model End Date | F16: Date | G16: =Statements!N7 -> 47477
B17: No. of Years Projected | F17: Years | G17: =YEARFRAC(G15,G16,1) -> 4.9981752
B18: Days in an Year | F18: Days | G18: 365
C21: Table of Contents
C22: Particulars
B24: 1 | C24: Dashboard
B25: 2 | C25: Financials
B26: 3 | C26: Statements
B27: 4 | C27: Scenario
B28: 5 | C28: Assumptions
B29: 6 | C29: Schedule
B30: 7 | C30: Valuation
B31: 8 | C31: Beta
B32: 9 | C32: WACC
B33: 10 | C33: FCFF
B34: 11 | C34: Report
B35: 12 | C35: Ratio Analysis
B36: 13 | C36: Equity Report

Sheet Financials->

Sheet Statements
B2: =Dashboard!B2 -> Denny's Diner
B3: Financial statements
B4: =Dashboard!B4 -> (In $ thousands, except per share amounts)
B5: Active Scenario | D5: =Dashboard!G13 -> Street
B6: Historicals / Forecast | G6: Historicals | J6: Forecast | O6: CAGR | Q6: Notes
B7: Month / Year (A/E) | G7: 44920 | H7: =EDATE(G7,12) -> 45285 | I7: =EDATE(H7,12) -> 45651 | J7: =EDATE(I7,12) -> 46016 | K7: =EDATE(J7,12) -> 46381 | L7: =EDATE(K7,12) -> 46746 | M7: =EDATE(L7,12) -> 47112 | N7: =EDATE(M7,12) -> 47477 | O7: 22A - 25A | P7: 25A - 30E
B9: <-Back to dashboard
B11: Go to -> | C11: Income statement | E11: Balance statement
B15: Templete: | C15: Standard | E15: Source: | F15: Company Website
B16: Period type: | C16: Annual | E16: Decimals: | F16: Default
B17: Currency: | C17: Reported
B18: Units: | C18: USD
A20: # | B20: Income statement | G20: 44920 | H20: 45285 | I20: 45651 | J20: 46016 | K20: 46381 | L20: 46746 | M20: 47112 | N20: 47477
B22: Revenue:
B23: Company restaurant sales | G23: 199753 | H23: 215532 | I23: 211781 | J23: =Assumptions!J23 -> 213633.92 | K23: =Assumptions!K23 -> 218849.96 | L23: =Assumptions!L23 -> 228203.92 | M23: =Assumptions!M23 -> 238731.34 | N23: =Assumptions!N23 -> 251341.8
B24: Franchise and license revenue | G24: 256676 | H24: 248390 | I24: 240553 | J24: =Assumptions!J42 -> 241068.35 | K24: =Assumptions!K42 -> 245424.28 | L24: =Assumptions!L42 -> 254555.12 | M24: =Assumptions!M42 -> 264671.25 | N24: =Assumptions!N42 -> 276654.6
B25: Total operating revenue | G25: 456429 | H25: 463922 | I25: =SUM(I23:I24) -> 452334 | J25: =SUM(J23:J24) -> 454702.27 | K25: =SUM(K23:K24) -> 464274.24 | L25: =SUM(L23:L24) -> 482759.04 | M25: =SUM(M23:M24) -> 503402.59 | N25: =SUM(N23:N24) -> 527996.41
B26: Costs of company restaurant sales:
B27: Product costs | G27: 53617 | H27: 55789 | I27: 53931 | J27: =Assumptions!J86 -> 55718.533 | K27: =Assumptions!K86 -> 57048.894 | L27: =Assumptions!L86 -> 60191.558 | M27: =Assumptions!M86 -> 63708.953 | N27: =Assumptions!N86 -> 67525.477
B28: Payroll and benefits | G28: 76412 | H28: 80666 | I28: 80605 | J28: =Assumptions!J94 -> 81242.611 | K28: =Assumptions!K94 -> 84511.78 | L28: =Assumptions!L94 -> 91198.44 | M28: =Assumptions!M94 -> 98937.055 | N28: =Assumptions!N94 -> 108511.31
B29: Occupancy | G29: 15154 | H29: 16809 | I29: 18129 | J29: =Assumptions!J104 -> 15545.869 | K29: =Assumptions!K104 -> 16637.873 | L29: =Assumptions!L104 -> 17517.315 | M29: =Assumptions!M104 -> 17640.413 | N29: =Assumptions!N104 -> 18622.843
B30: Other operating expenses | G30: 34275 | H30: 34335 | I30: 37079 | J30: =Assumptions!J107 -> 35023.704 | K30: =Assumptions!K107 -> 36059.944 | L30: =Assumptions!L107 -> 38084.487 | M30: =Assumptions!M107 -> 39195.646 | N30: =Assumptions!N107 -> 41257.666
B31: Total costs of company restaurant sales | G31: =SUM(G27:G30) -> 179458 | H31: =SUM(H27:H30) -> 187599 | I31: =SUM(I27:I30) -> 189744 | J31: =SUM(J27:J30) -> 187530.72 | K31: =SUM(K27:K30) -> 194258.49 | L31: =SUM(L27:L30) -> 206991.8 | M31: =SUM(M27:M30) -> 219482.07 | N31: =SUM(N27:N30) -> 235917.29
B33: Costs of franchise and license revenue | G33: 135327 | H33: 122452 | I33: 120226 | J33: =Assumptions!J119 -> 122250.35 | K33: =Assumptions!K119 -> 122584.66 | L33: =Assumptions!L119 -> 128099.44 | M33: =Assumptions!M119 -> 133401.97 | N33: =Assumptions!N119 -> 138979.76
B34: General and administrative expenses | G34: 67173 | H34: 77770 | I34: 80197 | J34: =Assumptions!J121 -> 74586.733 | K34: =Assumptions!K121 -> 78766.623 | L34: =Assumptions!L121 -> 82227.636 | M34: =Assumptions!M121 -> 84574.678 | N34: =Assumptions!N121 -> 89405.624
B35: Depreciation and amortization | G35: 14862 | H35: 14385 | I35: 14857 | J35: =Schedule!J27+Schedule!J45+Schedule!J60 -> 13724.577 | K35: =Schedule!K27+Schedule!K45+Schedule!K60 -> 13914.684 | L35: =Schedule!L27+Schedule!L45+Schedule!L60 -> 14602.521 | M35: =Schedule!M27+Schedule!M45+Schedule!M60 -> 15365.381 | N35: =Schedule!N27+Schedule!N45+Schedule!N60 -> 16163.077
B36: Goodwill impairment charges | G36: 0 | H36: 6363 | I36: 20 | J36: 0 | K36: 0 | L36: 0 | M36: 0 | N36: 0
B37: Operating (gains), losses and other charges, net | G37: -1005 | H37: 2530 | I37: 1974 | J37: 0 | K37: 0 | L37: 0 | M37: 0 | N37: 0
B38: Total operating costs and expenses, net | G38: 395815 | H38: 411099 | I38: 407018 | J38: =SUM(J33:J37)+J31 -> 398092.38 | K38: =SUM(K33:K37)+K31 -> 409524.46 | L38: =SUM(L33:L37)+L31 -> 431921.39 | M38: =SUM(M33:M37)+M31 -> 452824.1 | N38: =SUM(N33:N37)+N31 -> 480465.75
B40: Operating income | G40: 60614 | H40: 52823 | I40: 45316 | J40: =J25-J38 -> 56609.888 | K40: =K25-K38 -> 54749.777 | L40: =L25-L38 -> 50837.643 | M40: =M25-M38 -> 50578.488 | N40: =N25-N38 -> 47530.66
B41: Interest expense, net | G41: 13769 | H41: 17597 | I41: 17974 | J41: =Schedule!J95+Schedule!J110 -> 16021.14 | K41: =Schedule!K95+Schedule!K110 -> 12912.75 | L41: =Schedule!L95+Schedule!L110 -> 9910.15 | M41: =Schedule!M95+Schedule!M110 -> 7234.5 | N41: =Schedule!N95+Schedule!N110 -> 4563.2
B42: Other nonoperating income, net | G42: -52585 | H42: 8288 | I42: -1907 | J42: 0 | K42: 0 | L42: 0 | M42: 0 | N42: 0
B43: Net income before income taxes | G43: 99430 | H43: 26938 | I43: 29249 | J43: =J40-SUM(J41:J42) -> 40588.748 | K43: =K40-SUM(K41:K42) -> 41837.027 | L43: =L40-SUM(L41:L42) -> 40927.493 | M43: =M40-SUM(M41:M42) -> 43343.988 | N43: =N40-SUM(N41:N42) -> 42967.46
B44: Provision for income taxes | G44: 24718 | H44: 6993 | I44: 7678 | J44: =Assumptions!J124 -> 10553.074 | K44: =Assumptions!K124 -> 10877.627 | L44: =Assumptions!L124 -> 10641.148 | M44: =Assumptions!M124 -> 11269.437 | N44: =Assumptions!N124 -> 11171.54
B45: Net income | G45: 74712 | H45: 19945 | I45: 21571 | J45: =J43-J44 -> 30035.673 | K45: =K43-K44 -> 30959.4 | L45: =L43-L44 -> 30286.345 | M45: =M43-M44 -> 32074.551 | N45: =N43-N44 -> 31795.921
B47: Earnings per Share
B48: Basic | G48: =G$45/G52 -> 1.2294022 | H48: =H$45/H52 -> 0.3562625 | I48: =I$45/I52 -> 0.41088402 | J48: =J$45/J52 -> 0.57211896 | K48: =K$45/K52 -> 0.58971409 | L48: =L$45/L52 -> 0.57689375 | M48: =M$45/M52 -> 0.61095547 | N48: =N$45/N52 -> 0.60564812
B49: Diluted | G49: =G$45/G53 -> 1.2272212 | H49: =H$45/H53 -> 0.3549185 | I49: =I$45/I53 -> 0.40998594 | J49: =J$45/J53 -> 0.57086846 | K49: =K$45/K53 -> 0.58842514 | L49: =L$45/L53 -> 0.57563282 | M49: =M$45/M53 -> 0.60962009 | N49: =N$45/N53 -> 0.60432434
B51: Weighted Average Shares Outstanding
B52: Basic | G52: 60771 | H52: 55984 | I52: 52499 | J52: =I52 -> 52499 | K52: =J52 -> 52499 | L52: =K52 -> 52499 | M52: =L52 -> 52499 | N52: =M52 -> 52499
...

Sheet Assumptions
B2: =Dashboard!B2 -> Denny's Diner
B3: Assumptions
B4: =Dashboard!B4 -> (In $ thousands, except per share amounts)
B5: Active Scenario | D5: =Dashboard!G13 -> Street
B6: Historicals / Forecast | G6: Historicals | J6: Forecast | O6: CAGR | Q6: Notes
B7: Month / Year (A/E) | G7: =Statements!G7 -> 44920 | H7: =EDATE(G7,12) -> 45285 | I7: =EDATE(H7,12) -> 45651 | J7: =EDATE(I7,12) -> 46016 | K7: =EDATE(J7,12) -> 46381 | L7: =EDATE(K7,12) -> 46746 | M7: =EDATE(L7,12) -> 47112 | N7: =EDATE(M7,12) -> 47477 | O7: 22A - 24A | P7: 25E - 29E
B9: <-Back to dashboard
B11: Go to -> | C11: Revenue forecast | E11: Expense forecast
B13: Senarios
B14: Optimistic
B15: Street
B16: Pessimistic
A18: # | B18: Revenue Forecast ($ thousands) | G18: 44920 | H18: 45285 | I18: 45651 | J18: 46016 | K18: 46381 | L18: 46746 | M18: 47112 | N18: 47477
B20: Company restaurant sales:
B21: Denny's | G21: 193576 | H21: 201175 | I21: 193572 | J21: =I21*(1+J$77) -> 193313.73 | K21: =J21*(1+K$77) -> 196154.68 | L21: =K21*(1+L$77) -> 202869.65 | M21: =L21*(1+M$77) -> 210230.3 | N21: =M21*(1+N$77) -> 218882.28
B22: Others (Keke's) | G22: 6177 | H22: 14357 | I22: 18209 | J22: =I22*(1+J$79) -> 20320.188 | K22: =J22*(1+K$79) -> 22695.275 | L22: =K22*(1+L$79) -> 25334.261 | M22: =L22*(1+M$79) -> 28501.043 | N22: =M22*(1+N$79) -> 32459.522
B23: Total company restaurant sales | G23: =SUM(G21:G22) -> 199753 | H23: =SUM(H21:H22) -> 215532 | I23: =SUM(I21:I22) -> 211781 | J23: =SUM(J21:J22) -> 213633.92 | K23: =SUM(K21:K22) -> 218849.96 | L23: =SUM(L21:L22) -> 228203.92 | M23: =SUM(M21:M22) -> 238731.34 | N23: =SUM(N21:N22) -> 251341.8 | O23: =_xlfn.RRI(2,G23,I23) -> 0.029667114 | P23: =_xlfn.RRI(4,J23,N23) -> 0.041474472
B25: Franchise and license revenue:
B26: Royalties
B27: Denny's | G27: 111718 | H27: 115004 | I27: 113804 | J27: =I27*(1+J$77) -> 113652.16 | K27: =J27*(1+K$77) -> 115322.4 | L27: =K27*(1+L$77) -> 119270.24 | M27: =L27*(1+M$77) -> 123597.67 | N27: =M27*(1+N$77) -> 128684.31
B28: Others (Keke's) | G28: 2173 | H28: 5127 | I28: 4901 | J28: =I28*(1+J$79) -> 5469.2319 | K28: =J28*(1+K$79) -> 6108.4928 | L28: =K28*(1+L$79) -> 6818.7826 | M28: =L28*(1+M$79) -> 7671.1304 | N28: =M28*(1+N$79) -> 8736.5652
B29: Total | G29: =SUM(G27:G28) -> 113891 | H29: =SUM(H27:H28) -> 120131 | I29: =SUM(I27:I28) -> 118705 | J29: =SUM(J27:J28) -> 119121.39 | K29: =SUM(K27:K28) -> 121430.89 | L29: =SUM(L27:L28) -> 126089.02 | M29: =SUM(M27:M28) -> 131268.8 | N29: =SUM(N27:N28) -> 137420.87 | O29: =_xlfn.RRI(2,G29,I29) -> 0.020915513 | P29: =_xlfn.RRI(4,J29,N29) -> 0.036372158
B30: Advertising revenue
B31: Denny's | G31: 75926 | H31: 77932 | I31: 78192 | J31: =I31*(1+J$77) -> 78087.674 | K31: =J31*(1+K$77) -> 79235.256 | L31: =K31*(1+L$77) -> 81947.72 | M31: =L31*(1+M$77) -> 84920.998 | N31: =M31*(1+N$77) -> 88415.904
B32: Others (Keke's) | G32: 0 | H32: 562 | I32: 1781 | J32: =I32*(1+J$79) -> 1987.4928 | K32: =J32*(1+K$79) -> 2219.7971 | L32: =K32*(1+L$79) -> 2477.913 | M32: =L32*(1+M$79) -> 2787.6522 | N32: =M32*(1+N$79) -> 3174.8261
B33: Total | G33: =SUM(G31:G32) -> 75926 | H33: =SUM(H31:H32) -> 78494 | I33: =SUM(I31:I32) -> 79973 | J33: =SUM(J31:J32) -> 80075.167 | K33: =SUM(K31:K32) -> 81455.053 | L33: =SUM(L31:L32) -> 84425.633 | M33: =SUM(M31:M32) -> 87708.65 | N33: =SUM(N31:N32) -> 91590.73 | O33: =_xlfn.RRI(2,G33,I33) -> 0.026304974 | P33: =_xlfn.RRI(4,J33,N33) -> 0.034161621
B34: Initial and other fees
B35: Denny's | G35: 27870 | H35: 13112 | I35: 8351 | J35: =I35*(1+J$77) -> 8339.8579 | K35: =J35*(1+K$77) -> 8462.4209 | L35: =K35*(1+L$77) -> 8752.1154 | M35: =L35*(1+M$77) -> 9069.6651 | N35: =M35*(1+N$77) -> 9442.9253
B36: Others (Keke's) | G36: 392 | H36: 770 | I36: 360 | J36: =I36*(1+J$79) -> 401.73913 | K36: =J36*(1+K$79) -> 448.69565 | L36: =K36*(1+L$79) -> 500.86957 | M36: =L36*(1+M$79) -> 563.47826 | N36: =M36*(1+N$79) -> 641.73913
B37: Total | G37: =SUM(G35:G36) -> 28262 | H37: =SUM(H35:H36) -> 13882 | I37: =SUM(I35:I36) -> 8711 | J37: =SUM(J35:J36) -> 8741.597 | K37: =SUM(K35:K36) -> 8911.1166 | L37: =SUM(L35:L36) -> 9252.985 | M37: =SUM(M35:M36) -> 9633.1434 | N37: =SUM(N35:N36) -> 10084.664 | O37: =_xlfn.RRI(2,G37,I37) -> -0.4448216 | P37: =_xlfn.RRI(4,J37,N37) -> 0.036376763
B38: Occupancy revenue
B39: Denny's | G39: 38597 | H39: 35883 | I39: 33075 | J39: =I39*(1+J$77) -> 33030.871 | K39: =J39*(1+K$77) -> 33516.294 | L39: =K39*(1+L$77) -> 34663.659 | M39: =L39*(1+M$77) -> 35921.348 | N39: =M39*(1+N$77) -> 37399.683
B40: Others (Keke's) | G40: 0 | H40: 0 | I40: 89 | J40: =I40*(1+J$79) -> 99.318841 | K40: =J40*(1+K$79) -> 110.92754 | L40: =K40*(1+L$79) -> 123.82609 | M40: =L40*(1+M$79) -> 139.30435 | N40: =M40*(1+N$79) -> 158.65217
B41: Total | G41: =SUM(G39:G40) -> 38597 | H41: =SUM(H39:H40) -> 35883 | I41: =SUM(I39:I40) -> 33164 | J41: =SUM(J39:J40) -> 33130.189 | K41: =SUM(K39:K40) -> 33627.222 | L41: =SUM(L39:L40) -> 34787.485 | M41: =SUM(M39:M40) -> 36060.652 | N41: =SUM(N39:N40) -> 37558.335 | O41: =_xlfn.RRI(2,G41,I41) -> -0.073049211 | P41: =_xlfn.RRI(4,J41,N41) -> 0.031859588
B42: Total Franchise and license revenue | G42: =G29+G33+G37+G41 -> 256676 | H42: =H29+H33+H37+H41 -> 248390 | I42: =I29+I33+I37+I41 -> 240553 | J42: =J29+J33+J37+J41 -> 241068.35 | K42: =K29+K33+K37+K41 -> 245424.28 | L42: =L29+L33+L37+L41 -> 254555.12 | M42: =M29+M33+M37+M41 -> 264671.25 | N42: =N29+N33+N37+N41 -> 276654.6 | O42: =_xlfn.RRI(2,G42,I42) -> -0.031916635 | P42: =_xlfn.RRI(4,J42,N42) -> 0.035021637
B44: Total revenue from Denny's | G44: =G21+G27+G31+G35+G39 -> 447687 | H44: =H21+H27+H31+H35+H39 -> 443106 | I44: =I21+I27+I31+I35+I39 -> 426994 | J44: =J21+J27+J31+J35+J39 -> 426424.29 | K44: =K21+K27+K31+K35+K39 -> 432691.05 | L44: =L21+L27+L31+L35+L39 -> 447503.38 | M44: =M21+M27+M31+M35+M39 -> 463739.98 | N44: =N21+N27+N31+N35+N39 -> 482825.1
B45: Total revenue from Keke's | G45: =G22+G28+G32+G36+G40 -> 8742 | H45: =H22+H28+H32+H36+H40 -> 20816 | I45: =I22+I28+I32+I36+I40 -> 25340 | J45: =J22+J28+J32+J36+J40 -> 28277.971 | K45: =K22+K28+K32+K36+K40 -> 31583.188 | L45: =L22+L28+L32+L36+L40 -> 35255.652 | M45: =M22+M28+M32+M36+M40 -> 39662.609 | N45: =N22+N28+N32+N36+N40 -> 45171.304
B46: Total Revenue | G46: =G23+G42 -> 456429 | H46: =H23+H42 -> 463922 | I46: =I23+I42 -> 452334 | J46: =J23+J42 -> 454702.27 | K46: =K23+K42 -> 464274.24 | L46: =L23+L42 -> 482759.04 | M46: =M23+M42 -> 503402.59 | N46: =N23+N42 -> 527996.41
B48: Analysis
B49: Company-owned restaurants
...

Sheet Schedule
B2: =Dashboard!B2 -> Denny's Diner
B3: Schedule
B4: =Dashboard!B4 -> (In $ thousands, except per share amounts)
B5: Active Scenario | D5: =Dashboard!G13 -> Street
B6: Historicals / Forecast | G6: Historicals | J6: Forecast
B7: Month / Year (A/E) | G7: =Statements!G7 -> 44920 | H7: =EDATE(G7,12) -> 45285 | I7: =EDATE(H7,12) -> 45651 | J7: =EDATE(I7,12) -> 46016 | K7: =EDATE(J7,12) -> 46381 | L7: =EDATE(K7,12) -> 46746 | M7: =EDATE(L7,12) -> 47112 | N7: =EDATE(M7,12) -> 47477
B9: <-Back to dashboard
B11: Go to -> | C11: PP&E and intangibles | E11: Working capital | G11: Equity schedule
A13: # | B13: PP&E and Intangible schedule | G13: 44920 | H13: 45285 | I13: 45651 | J13: 46016 | K13: 46381 | L13: 46746 | M13: 47112 | N13: 47477
B15: Property, plant and equipment
B17: Opening balance of Gross PP&E | H17: =G20 -> 243012 | I17: =H20 -> 253373 | J17: =I20 -> 271005 | K17: =J20 -> 275599.05 | L17: =K20 -> 282813.08 | M17: =L20 -> 291599.3 | N17: =M20 -> 302987.76
B18: Additons to PP&E | J18: =J24 -> 9094.0453 | K18: =K24 -> 10214.033 | L18: =L24 -> 11586.217 | M18: =M24 -> 13088.467 | N18: =N24 -> 14783.899
B19: Disposal of PP&E | J19: -4500 | K19: -3000 | L19: -2800 | M19: -1700 | N19: -1500
B20: Closing balance of Gross PP&E | G20: 243012 | H20: 253373 | I20: 271005 | J20: =SUM(J17:J19) -> 275599.05 | K20: =SUM(K17:K19) -> 282813.08 | L20: =SUM(L17:L19) -> 291599.3 | M20: =SUM(M17:M19) -> 302987.76 | N20: =SUM(N17:N19) -> 316271.66
B21: Less: Accumulated depreciation | I21: 159588 | J21: =I21+J27 -> 171494.71 | K21: =J21+K27 -> 183472.9 | L21: =K21+L27 -> 195827.56 | M21: =L21+M27 -> 208747.5 | N21: =M21+N27 -> 222174.72
B22: Closing balance of Net, PP&E | J22: =J20-J21 -> 104104.34 | K22: =K20-K21 -> 99340.177 | L22: =L20-L21 -> 95771.74 | M22: =M20-M21 -> 94240.268 | N22: =N20-N21 -> 94096.945
B24: CapEx related to PP&E | G24: =4596+91+3846 -> 8533 | H24: =349+4378+3782 -> 8509 | I24: =7471+14970+3420 -> 25861 | J24: =J25*Statements!J25 -> 9094.0453 | K24: =K25*Statements!K25 -> 10214.033 | L24: =L25*Statements!L25 -> 11586.217 | M24: =M25*Statements!M25 -> 13088.467 | N24: =N25*Statements!N25 -> 14783.899
B25: CapEx as a % of Revenue | G25: =G24/Statements!G25 -> 0.018695131 | H25: =H24/Statements!H25 -> 0.018341445 | I25: =I24/Statements!I25 -> 0.057172355 | J25: 0.02 | K25: 0.022 | L25: 0.024 | M25: 0.026 | N25: 0.028
B27: Depreciation of PP&E | G27: 11118 | H27: 10720 | I27: 11260 | J27: =J28*J20 -> 11906.709 | K27: =K28*K20 -> 11978.192 | L27: =L28*L20 -> 12354.654 | M27: =M28*M20 -> 12919.939 | N27: =N28*N20 -> 13427.222
B28: Depreciation as a % of Gross closing PP&E | G28: =G27/G20 -> 0.045750827 | H28: =H27/H20 -> 0.042309165 | I28: =I27/I20 -> 0.041549049 | J28: =AVERAGE(G28:I28) -> 0.043203014 | K28: =AVERAGE(H28:J28) -> 0.042353742 | L28: =AVERAGE(I28:K28) -> 0.042368602 | M28: =AVERAGE(J28:L28) -> 0.042641786 | N28: =AVERAGE(K28:M28) -> 0.04245471
B30: Intangible Assets
B32: Intangible assets with indefinte life | G32: =79687+120 -> 79807 | H32: =79687+120 -> 79807 | I32: =79687+120 -> 79807 | J32: =I32 -> 79807 | K32: =J32 -> 79807 | L32: =K32 -> 79807 | M32: =L32 -> 79807 | N32: =M32 -> 79807
B33: Intangible assets with definte life | G33: =10489+10700 -> 21189 | H33: =9470+10700 -> 20170 | I33: =9135+10603 -> 19738 | J33: =J42+I33 -> 21453.828 | K33: =K42+J33 -> 22895.312 | L33: =L42+K33 -> 24606.953 | M33: =M42+L33 -> 26356.088 | N33: =N42+M33 -> 28138.071
B36: Opening balance of Intangible assets | H36: =G38 -> 100996 | I36: =H38 -> 99977 | J36: =I38 -> 99545 | K36: =J38 -> 101260.83 | L36: =K38 -> 102702.31 | M36: =L38 -> 104413.95 | N36: =M38 -> 106163.09
B37: Additions to intangibles | H37: =H38-H36 -> -1019 | I37: =I38-I36 -> -432 | J37: =J42 -> 1715.8284 | K37: =K42 -> 1441.4837 | L37: =L42 -> 1711.6409 | M37: =M42 -> 1749.1345 | N37: =N42 -> 1781.9832
B38: Closing balance of Intangible assets | G38: 100996 | H38: 99977 | I38: 99545 | J38: =SUM(J36:J37) -> 101260.83 | K38: =SUM(K36:K37) -> 102702.31 | L38: =SUM(L36:L37) -> 104413.95 | M38: =SUM(M36:M37) -> 106163.09 | N38: =SUM(N36:N37) -> 107945.07
B39: Less: Accumulated amortization | I39: 7806 | J39: =I39+J45 -> 9591.1657 | K39: =J39+K45 -> 11496.628 | L39: =K39+L45 -> 13705.419 | M39: =L39+M45 -> 16114.036 | N39: =M39+N45 -> 18811.05
B40: Closing balance of Net, Intangibles | J40: =J38-J39 -> 91669.663 | K40: =K38-K39 -> 91205.684 | L40: =L38-L39 -> 90708.534 | M40: =M38-M39 -> 90049.051 | N40: =N38-N39 -> 89134.02
B42: CapEx related to intangibles | G42: 2638 | H42: 827 | I42: 1700 | J42: =J43*Statements!J25 -> 1715.8284 | K42: =K43*Statements!K25 -> 1441.4837 | L42: =L43*Statements!L25 -> 1711.6409 | M42: =M43*Statements!M25 -> 1749.1345 | N42: =N43*Statements!N25 -> 1781.9832
B43: CapEx as a % of Revenue | G43: =G42/Statements!G25 -> 0.0057796503 | H43: =H42/Statements!H25 -> 0.0017826273 | I43: =I42/Statements!I25 -> 0.0037582848 | J43: {=AVERAGE(G43:I43)} -> 0.0037735208 | K43: {=AVERAGE(H43:J43)} -> 0.0031048109 | L43: {=AVERAGE(I43:K43)} -> 0.0035455388 | M43: {=AVERAGE(J43:L43)} -> 0.0034746235 | N43: {=AVERAGE(K43:M43)} -> 0.0033749911
B45: Total Amortization of Intangibles | G45: 2000 | H45: 2200 | I45: 2200 | J45: =SUM(J46:J52) -> 1785.1657 | K45: =SUM(K46:K52) -> 1905.4624 | L45: =SUM(L46:L52) -> 2208.7906 | M45: =SUM(M46:M52) -> 2408.6175 | N45: =SUM(N46:N52) -> 2697.0142
B46: Amortization of Intangibles (existing) | J46: 1442 | K46: 1274 | L46: 1235 | M46: 1085 | N46: 1017
B48: Amortization of Intangibles (new) | J48: =$J$42/5 -> 343.16569 | K48: =$J$42/5 -> 343.16569 | L48: =$J$42/5 -> 343.16569 | M48: =$J$42/5 -> 343.16569 | N48: =$J$42/5 -> 343.16569
K49: =$K$42/5 -> 288.29675 | L49: =$K$42/5 -> 288.29675 | M49: =$K$42/5 -> 288.29675 | N49: =$K$42/5 -> 288.29675
L50: =$L$42/5 -> 342.32818 | M50: =$L$42/5 -> 342.32818 | N50: =$L$42/5 -> 342.32818
M51: =$M$42/5 -> 349.8269 | N51: =$M$42/5 -> 349.8269
N52: =$N$42/5 -> 356.39664
B53: Other non-current assets
B55: Opening balance of NCA | J55: =Statements!I72 -> 54764 | K55: =J58 -> 49405.293 | L55: =K58 -> 50010.28 | M55: =L58 -> 54300.914 | N55: =M58 -> 55181.589
B56: Additons to NCA | J56: =J58-J57-J55 -> -5326.0052 | K56: =K58-K57-K55 -> 636.01643 | L56: =L58-L57-L55 -> 4329.7098 | M56: =M58-M57-M55 -> 917.49965 | N56: =N58-N57-N55 -> 2904.2433
...

Sheet Valuation->
A1: \

Sheet WACC
B2: =Dashboard!B2 -> Denny's Diner
B3: WACC
B4: (In $ Millions, except per share amounts and shares outstanding)
B5: Active Scenario | C5: =Dashboard!G13 -> Street
B8: <-Back to dashboard
B10: Company name | C10: Equity Value | D10: Debt | E10: Tax Rate | F10: Levered Beta | G10: Un-Levered Beta
B12: Denny's Diner | C12: =Comp_Comps!F22 -> 328.8375 | D12: =Comp_Comps!G22 -> 211.3 | E12: 0.25 | F12: 1.37 | G12: =F12/(1+(1-E12)*(D12/C12)) -> 0.92447326
B13: Dine Brands Global, Inc. | C13: =Comp_Comps!F15 -> 367.164 | D13: =Comp_Comps!G15 -> 1600 | E13: 0.25 | F13: 0.94 | G13: =F13/(1+(1-E13)*(D13/C13)) -> 0.22022849
B14: Cracker Barrel Old Country Store, Inc. | C14: =Comp_Comps!F16 -> 617.5305 | D14: =Comp_Comps!G16 -> 1210 | E14: 0.25 | F14: 1.22 | G14: =F14/(1+(1-E14)*(D14/C14)) -> 0.49401452
B15: Texas Roadhouse, Inc. | C15: =Comp_Comps!F17 -> 11305.035 | D15: =Comp_Comps!G17 -> 976.76 | E15: 0.25 | F15: 0.87 | G15: =F15/(1+(1-E15)*(D15/C15)) -> 0.81705459
B16: Brinker International, Inc. | C16: =Comp_Comps!F18 -> 6275.7375 | D16: =Comp_Comps!G18 -> 1760 | E16: 0.25 | F16: 1.36 | G16: =F16/(1+(1-E16)*(D16/C16)) -> 1.1236569
B17: Darden Restaurants, Inc. | C17: =Comp_Comps!F19 -> 23079.393 | D17: =Comp_Comps!G19 -> 8350 | E17: 0.25 | F17: 0.6 | G17: =F17/(1+(1-E17)*(D17/C17)) -> 0.47194078
B18: Papa John's International, Inc. | C18: =Comp_Comps!F20 -> 1185.0972 | D18: =Comp_Comps!G20 -> 937.1 | E18: 0.25 | F18: 1.24 | G18: =F18/(1+(1-E18)*(D18/C18)) -> 0.77837981
D20: Average | E20: =AVERAGE(E12:E18) -> 0.25 | F20: =AVERAGE(F12:F18) -> 1.0857143 | G20: =AVERAGE(G12:G18) -> 0.68996405
D21: Median | E21: {=MEDIAN(E12:E18)} -> 0.25 | F21: {=MEDIAN(F12:F18)} -> 1.22 | G21: {=MEDIAN(G12:G18)} -> 0.77837981
B23: Cost of Debt | E23: Weightage
B24: Pre-Tax Cost of debt | C24: =((Statements!J41/1000)/(Statements!J83/1000)) -> 0.07582177 | E24: Equity | G24: =C12 -> 328.8375
B25: Tax Rate | C25: =E21 -> 0.25 | E25: Debt | G25: =D12 -> 211.3
B26: Post-Tax Cost of debt | C26: =C24*(1-C25) -> 0.056866327 | E26: Total | G26: =SUM(G24:G25) -> 540.1375
B28: Cost of Equity | E28: Weighted average cost of capital
B29: Risk free rate | C29: 0.0421 | E29: Cost of Debt | G29: =C26*(G25/G26) -> 0.022245919
B30: Equity risk premium | C30: 0.0446 | E30: Cost of Equity | G30: =C33*(G24/G26) -> 0.060157073
B31: Country risk | C31: 0.0023 | E31: WACC | G31: =G29+G30 -> 0.082402992
B32: Levered Beta | C32: =F21 -> 1.22
B33: Cost of Equity | C33: =C29+(C30*C32)+C31 -> 0.098812

Sheet Comp_Comps
B2: =Dashboard!B2 -> Denny's Diner
B3: Company Comparables
B4: (In $ Millions, except per share amounts and shares outstanding)
B5: Active Scenario | D5: =Dashboard!G13 -> Street
B8: <-Back to dashboard
B10: Comparable companies - US-based operating family-style dine-in & QSR's (In $ Millions)
B12: Valuation statistics
B14: Company name | C14: Ticker | D14: Share price | E14: Diluted Shares | F14: Equity Value | G14: Debt | H14: Cash | I14: Enterprise Value | J14: Revenue | K14: EBITDA | L14: Net Income | M14: EV/Revenue | N14: EV/EBITDA | O14: P/E Multiple
B15: Dine Brands Global, Inc. | C15: IHP.F | D15: 25.2 | E15: 14.57 | F15: =D15*E15 -> 367.164 | G15: 1600 | H15: 128.2 | I15: =F15+G15-H15 -> 1838.964 | J15: 879.3 | K15: 186.5 | L15: 16 | M15: =I15/J15 -> 2.0913954 | N15: =I15/K15 -> 9.8603968 | O15: =D15/(L15/E15) -> 22.94775
B16: Cracker Barrel Old Country Store, Inc. | C16: CBRL | D16: 27.63 | E16: 22.35 | F16: =D16*E16 -> 617.5305 | G16: 1210 | H16: 8.57 | I16: =F16+G16-H16 -> 1818.9605 | J16: 3360 | K16: 130.87 | L16: -4.01 | M16: =I16/J16 -> 0.54135729 | N16: =I16/K16 -> 13.898988 | O16: =D16/(L16/E16) -> -153.99763
B17: Texas Roadhouse, Inc. | C17: TXRH | D17: 170.9 | E17: 66.15 | F17: =D17*E17 -> 11305.035 | G17: 976.76 | H17: 134.71 | I17: =F17+G17-H17 -> 12147.085 | J17: 5880 | K17: 681.73 | L17: 405.55 | M17: =I17/J17 -> 2.0658308 | N17: =I17/K17 -> 17.818029 | O17: =D17/(L17/E17) -> 27.875811
B18: Brinker International, Inc. | C18: EAT | D18: 141.25 | E18: 44.43 | F18: =D18*E18 -> 6275.7375 | G18: 1760 | H18: 15 | I18: =F18+G18-H18 -> 8020.7375 | J18: 5690 | K18: 809.9 | L18: 454.1 | M18: =I18/J18 -> 1.4096199 | N18: =I18/K18 -> 9.9033677 | O18: =D18/(L18/E18) -> 13.820166
B19: Darden Restaurants, Inc. | C19: DRI | D19: 198.43 | E19: 116.31 | F19: =D19*E19 -> 23079.393 | G19: 8350 | H19: 224.1 | I19: =F19+G19-H19 -> 31205.293 | J19: 12580 | K19: 1990 | L19: 1120 | M19: =I19/J19 -> 2.480548 | N19: =I19/K19 -> 15.681052 | O19: =D19/(L19/E19) -> 20.606601
B20: Papa John's International, Inc. | C20: PZZA | D20: 36.12 | E20: 32.81 | F20: =D20*E20 -> 1185.0972 | G20: 937.1 | H20: 36.95 | I20: =F20+G20-H20 -> 2085.2472 | J20: 2050 | K20: 201.79 | L20: 29.57 | M20: =I20/J20 -> 1.0171938 | N20: =I20/K20 -> 10.333749 | O20: =D20/(L20/E20) -> 40.077687
B22: Denny's Diner | C22: DENN | D22: 6.25 | E22: =Statements!J53/1000 -> 52.614 | F22: =D22*E22 -> 328.8375 | G22: =Statements!J83/1000 -> 211.3 | H22: =Statements!J59/1000 -> 2.2655068 | I22: =F22+G22-H22 -> 537.87199 | J22: =Statements!J25/1000 -> 454.70227 | K22: =(Statements!J40+Statements!J35)/1000 -> 70.334464 | L22: =Statements!J45/1000 -> 30.035673 | M22: =I22/J22 -> 1.1829103 | N22: =I22/K22 -> 7.6473461 | O22: =D22/(L22/E22) -> 10.948231
L23: Maxminum | M23: =MAX(M15:M20) -> 2.480548 | N23: =MAX(N15:N20) -> 17.818029 | O23: =MAX(O15:O20) -> 40.077687
L24: 75th percentile | M24: =QUARTILE(M15:M20,3) -> 2.0850043 | N24: =QUARTILE(N15:N20,3) -> 15.235536 | O24: =QUARTILE(O15:O20,3) -> 26.643795
L25: Median | M25: =MEDIAN(M15:M20) -> 1.7377254 | N25: =MEDIAN(N15:N20) -> 12.116368 | O25: =MEDIAN(O15:O20) -> 21.777176
L26: 25th percentile | M26: =QUARTILE(M15:M20,1) -> 1.1153003 | N26: =QUARTILE(N15:N20,1) -> 10.010963 | O26: =QUARTILE(O15:O20,1) -> 15.516775
L27: Minimum | M27: =MIN(M15:M20) -> 0.54135729 | N27: =MIN(N15:N20) -> 9.8603968 | O27: =MIN(O15:O20) -> -153.99763

Sheet FCFF
B2: =Dashboard!B2 -> Denny's Diner
B3: FCFF
B4: =Dashboard!B4 -> (In $ thousands, except per share amounts)
B5: Active Scenario | D5: =Dashboard!G13 -> Street
B8: <-Back to dashboard
B10: Valuation parameters
B12: Valuation as on specified date | E12: 46016 | G12: Implied Price per Share | I12: =G40 -> 8.7223597
B13: Date of year ending | E13: 46022 | G13: Current Price | I13: =Comp_Comps!D22 -> 6.25
B14: Marginal Tax Rate (%) | E14: =WACC!E21 -> 0.25 | G14: Discount | (Premium) | I14: =I13/I12-1 -> -0.28345078
B15: WACC (%) | E15: =WACC!G31 -> 0.082402992
B16: Terminal Growth Rate (%) | E16: 0.02
B18: Free Cash Flow to Firm | G18: =Statements!J7 -> 46016 | H18: =EDATE(G18,12) -> 46381 | I18: =EDATE(H18,12) -> 46746 | J18: =EDATE(I18,12) -> 47112 | K18: =EDATE(J18,12) -> 47477
B20: EBIT | G20: =Statements!J40 -> 56609.888 | H20: =Statements!K40 -> 54749.777 | I20: =Statements!L40 -> 50837.643 | J20: =Statements!M40 -> 50578.488 | K20: =Statements!N40 -> 47530.66
B21: Tax rate (%) | G21: =$E$14 -> 0.25 | H21: =$E$14 -> 0.25 | I21: =$E$14 -> 0.25 | J21: =$E$14 -> 0.25 | K21: =$E$14 -> 0.25
B22: Less: Income taxes | G22: =G20*G21 -> 14152.472 | H22: =H20*H21 -> 13687.444 | I22: =I20*I21 -> 12709.411 | J22: =J20*J21 -> 12644.622 | K22: =K20*K21 -> 11882.665
B23: NOPAT | G23: =G20-G22 -> 42457.416 | H23: =H20-H22 -> 41062.333 | I23: =I20-I22 -> 38128.233 | J23: =J20-J22 -> 37933.866 | K23: =K20-K22 -> 35647.995
B25: Add: Depreciation and Amortisation | G25: =Statements!J107 -> 13724.577 | H25: =Statements!K107 -> 13914.684 | I25: =Statements!L107 -> 14602.521 | J25: =Statements!M107 -> 15365.381 | K25: =Statements!N107 -> 16163.077
B26: Add: Share-based compensation | G26: =Statements!J108 -> 7699.8804 | H26: =Statements!K108 -> 9677.7862 | I26: =Statements!L108 -> 9816.0015 | J26: =Statements!M108 -> 9548.1705 | K26: =Statements!N108 -> 9903.2566
B27: Add/Less: Change in Working capital | G27: =SUM(Statements!J111,Statements!J112,Statements!J114) -> -340.66134 | H27: =SUM(Statements!K111,Statements!K112,Statements!K114) -> 129.63285 | I27: =SUM(Statements!L111,Statements!L112,Statements!L114) -> 225.44902 | J27: =SUM(Statements!M111,Statements!M112,Statements!M114) -> 85.482171 | K27: =SUM(Statements!N111,Statements!N112,Statements!N114) -> 251.29206
B28: Less: Capital Expenditure | G28: =(Statements!J119+Statements!J121+Statements!J122) -> -5483.8685 | H28: =(Statements!K119+Statements!K121+Statements!K122) -> -12291.533 | I28: =(Statements!L119+Statements!L121+Statements!L122) -> -17627.568 | J28: =(Statements!M119+Statements!M121+Statements!M122) -> -15755.101 | K28: =(Statements!N119+Statements!N121+Statements!N122) -> -19470.126
B29: FCFF | G29: =SUM(G23:G28) -> 58057.343 | H29: =SUM(H23:H28) -> 52492.903 | I29: =SUM(I23:I28) -> 45144.637 | J29: =SUM(J23:J28) -> 47177.799 | K29: =SUM(K23:K28) -> 42495.496
B31: Dicount Rate | G31: =(E13-E12)/(365/2) -> 0.032876712 | H31: =G31+1 -> 1.0328767 | I31: =H31+1 -> 2.0328767 | J31: =I31+1 -> 3.0328767 | K31: =J31+1 -> 4.0328767
B32: Terminal Value | K32: =K29*(1+terminal_growth)/(wacc-terminal_growth) -> 694604.6
B33: PV of Cash Flows | G33: =G29/(1+wacc)^G31 -> 57906.399 | H33: =H29/(1+wacc)^H31 -> 48370.548 | I33: =I29/(1+wacc)^I31 -> 38432.408 | J33: =J29/(1+wacc)^J31 -> 37105.657 | K33: =(K29+K32)/(1+wacc)^K31 -> 535599.22
B34: Enterprise Value | G34: =SUM(G33:K33) -> 717414.23
B35: Add: Cash | G35: =Statements!I59 -> 1698
B36: Add: Investments & Securities | G36: =Statements!I60 -> 1106
B37: Less: Debt | G37: =-Statements!I83 -> -261300
B38: Equity Value | G38: =SUM(G34:G37) -> 458918.23
B39: No. of Shares | G39: =Statements!I53 -> 52614
B40: Price per Share | G40: =G38/G39 -> 8.7223597

Sheet Ratio Analysis
B2: =Dashboard!B2 -> Denny's Diner
B3: Ratio Analysis
B4: =Dashboard!B4 -> (In $ thousands, except per share amounts)
B5: Active Scenario | D5: =Dashboard!G13 -> Street
B6: Historicals / Forecast | G6: Historicals | J6: Forecast
B7: Month / Year (A/E) | G7: =Statements!G7 -> 44920 | H7: =EDATE(G7,12) -> 45285 | I7: =EDATE(H7,12) -> 45651 | J7: =EDATE(I7,12) -> 46016 | K7: =EDATE(J7,12) -> 46381 | L7: =EDATE(K7,12) -> 46746 | M7: =EDATE(L7,12) -> 47112 | N7: =EDATE(M7,12) -> 47477
B9: <-Back to dashboard

Sheet Report
A1: \

Sheet LBO_model
B2: =Dashboard!B2 -> Denny's Diner
B3: LBO Model
B4: =Dashboard!B4 -> (In $ thousands, except per share amounts)
Q5: Initial Cash Balance: | T5: =Y38 -> 2265.5068
B6: Denny's Diner LBO model as of FY 2025 | Q6: Minimum Cash Balance: | T6: -2000
B8: Transaction Assumptions | Q8: Income Statement | V8: Historical | Z8: Transaction Adjustments | AC8: Forecast
V9: 44920 | W9: 45285 | X9: 45651 | Y9: 46016 | Z9: Debit | AA9: Credit | AB9: 46016 | AC9: 46381 | AD9: 46746 | AE9: 47112 | AF9: 47477
B10: Current share price: | F10: 4.11 | H10: Equity purchase price: | L10: =F23 -> 328690.18
B11: Offer premium: | F11: 0.52 | H11: Enterprise value: | L11: =F29 -> 617931.21 | Q11: Revenue | V11: =Statements!G25 -> 456429 | W11: =Statements!H25 -> 463922 | X11: =Statements!I25 -> 452334 | Y11: =Statements!J25 -> 454702.27 | AC11: =Statements!K25 -> 464274.24 | AD11: =Statements!L25 -> 482759.04 | AE11: =Statements!M25 -> 503402.59 | AF11: =Statements!N25 -> 527996.41
B12: Offer price per share: | F12: =F10*(1+F11) -> 6.2472 | H12: EBITDA purchase multiple: | L12: =L11/(Comp_Comps!K22*1000) -> 8.7856105 | Q12: Costs of company restaurant sales | V12: =Statements!G31 -> 179458 | W12: =Statements!H31 -> 187599 | X12: =Statements!I31 -> 189744 | Y12: =Statements!J31 -> 187530.72 | AC12: =Statements!K31 -> 194258.49 | AD12: =Statements!L31 -> 206991.8 | AE12: =Statements!M31 -> 219482.07 | AF12: =Statements!N31 -> 235917.29
B13: Leverage ratio: | F13: 3 | H13: Debt required: | L13: =F13*(Comp_Comps!K22*1000) -> 211003.39
B14: Tax Rate: | F14: 0.26 | H14: Equity used: | L14: =L10-L13 -> 117686.79 | Q14: Costs of franchise and license revenue | V14: =Statements!G33 -> 135327 | W14: =Statements!H33 -> 122452 | X14: =Statements!I33 -> 120226 | Y14: =Statements!J33 -> 122250.35 | AC14: =Statements!K33 -> 122584.66 | AD14: =Statements!L33 -> 128099.44 | AE14: =Statements!M33 -> 133401.97 | AF14: =Statements!N33 -> 138979.76
H15: EBITDA exit multiple: | L15: 10 | Q15: General and administrative expenses | V15: =Statements!G34 -> 67173 | W15: =Statements!H34 -> 77770 | X15: =Statements!I34 -> 80197 | Y15: =Statements!J34 -> 74586.733 | AC15: =Statements!K34 -> 78766.623 | AD15: =Statements!L34 -> 82227.636 | AE15: =Statements!M34 -> 84574.678 | AF15: =Statements!N34 -> 89405.624
B16: Purchase price calculation | Q16: Depreciation and amortization | V16: =Statements!G35 -> 14862 | W16: =Statements!H35 -> 14385 | X16: =Statements!I35 -> 14857 | Y16: =Statements!J35 -> 13724.577 | AC16: =Statements!K35 -> 13914.684 | AD16: =Statements!L35 -> 14602.521 | AE16: =Statements!M35 -> 15365.381 | AF16: =Statements!N35 -> 16163.077
Q17: Depreciation of PP&E Write-Up: | AC17: =$L$65/$L$66 -> 1561.565 | AD17: =$L$65/$L$66 -> 1561.565 | AE17: =$L$65/$L$66 -> 1561.565 | AF17: =$L$65/$L$66 -> 1561.565
Q18: New Intangibles Amortization: | AC18: =$L$72/$L$73 -> 15713.465 | AD18: =$L$72/$L$73 -> 15713.465 | AE18: =$L$72/$L$73 -> 15713.465 | AF18: =$L$72/$L$73 -> 15713.465
Q19: Amortization of Financing Fees: | AC19: =$L$54/$F$76 -> 331.50509 | AD19: =$L$54/$F$76 -> 331.50509 | AE19: =$L$54/$F$76 -> 331.50509 | AF19: =$L$54/$F$76 -> 331.50509
B20: Basic shares outstanding: | F20: =Statements!J52 -> 52499 | H20: Advisory fee (%): | L20: 0.0025 | Q20: Goodwill impairment charges | V20: =Statements!G36 -> 0 | W20: =Statements!H36 -> 6363 | X20: =Statements!I36 -> 20 | Y20: =Statements!J36 -> 0 | AC20: =Statements!K36 -> 0 | AD20: =Statements!L36 -> 0 | AE20: =Statements!M36 -> 0 | AF20: =Statements!N36 -> 0
B21: Basic equity value: | F21: =F20*F12 -> 327971.75 | H21: Financing fee (%): | L21: 0.0075 | Q21: Operating (gains), losses and other charges, net | V21: =Statements!G37 -> -1005 | W21: =Statements!H37 -> 2530 | X21: =Statements!I37 -> 1974 | Y21: =Statements!J37 -> 0 | AC21: =Statements!K37 -> 0 | AD21: =Statements!L37 -> 0 | AE21: =Statements!M37 -> 0 | AF21: =Statements!N37 -> 0
B22: Diluted shares outstanding: | F22: =Statements!J53 -> 52614 | H22: Legal & Misc. fees (%): | L22: 0.005 | Q22: Total operating costs and expenses, net | V22: =Statements!G38 -> 395815 | W22: =Statements!H38 -> 411099 | X22: =Statements!I38 -> 407018 | Y22: =Statements!J38 -> 398092.38 | AC22: =SUM(AC14:AC21)+AC12 -> 427131 | AD22: =SUM(AD14:AD21)+AD12 -> 449527.93 | AE22: =SUM(AE14:AE21)+AE12 -> 470430.64 | AF22: =SUM(AF14:AF21)+AF12 -> 498072.28
B23: Diluted equity value: | F23: =F22*F12 -> 328690.18
B24: Less: Cash & cash equivalents: | F24: =-Statements!J59 -> -2265.5068 | Q24: Operating income | V24: =Statements!G40 -> 60614 | W24: =Statements!H40 -> 52823 | X24: =Statements!I40 -> 45316 | Y24: =Statements!J40 -> 56609.888 | AC24: =AC11-AC22 -> 37143.242 | AD24: =AD11-AD22 -> 33231.108 | AE24: =AE11-AE22 -> 32971.953 | AF24: =AF11-AF22 -> 29924.125
B25: Add: Debt: | F25: =Statements!J83 -> 211300
B26: Add: Minority interest: | F26: 0 | Q26: Interest expense, net | V26: =Statements!G41 -> 13769 | W26: =Statements!H41 -> 17597 | X26: =Statements!I41 -> 17974 | Y26: =Statements!J41 -> 16021.14 | AC26: =Statements!K41+(-AC150) -> 31630.4 | AD26: =Statements!L41+(-AD150) -> 26970.465 | AE26: =Statements!M41+(-AE150) -> 22975.306 | AF26: =Statements!N41+(-AF150) -> 19355.878
B27: Add: Preferred stock: | F27: 0 | Q27: Other nonoperating income, net | V27: =Statements!G42 -> -52585 | W27: =Statements!H42 -> 8288 | X27: =Statements!I42 -> -1907 | Y27: =Statements!J42 -> 0 | AC27: =Statements!K42 -> 0 | AD27: =Statements!L42 -> 0 | AE27: =Statements!M42 -> 0 | AF27: =Statements!N42 -> 0
B28: Add: Other liabilities: | F28: =Statements!J80+Statements!J79+Statements!J77 -> 80206.536 | Q28: Net income before income taxes | V28: =Statements!G43 -> 99430 | W28: =Statements!H43 -> 26938 | X28: =Statements!I43 -> 29249 | Y28: =Statements!J43 -> 40588.748 | AC28: =AC24-AC26-AC27 -> 5512.8422 | AD28: =AD24-AD26-AD27 -> 6260.6431 | AE28: =AE24-AE26-AE27 -> 9996.6473 | AF28: =AF24-AF26-AF27 -> 10568.248
B29: Enterprise value: | F29: =SUM(F23:F28) -> 617931.21 | Q29: Provision for income taxes | V29: =Statements!G44 -> 24718 | W29: =Statements!H44 -> 6993 | X29: =Statements!I44 -> 7678 | Y29: =Statements!J44 -> 10553.074 | AC29: =AC28*26% -> 1433.339 | AD29: =AD28*26% -> 1627.7672 | AE29: =AE28*26% -> 2599.1283 | AF29: =AF28*26% -> 2747.7444
Q30: Net income | V30: =Statements!G45 -> 74712 | W30: =Statements!H45 -> 19945 | X30: =Statements!I45 -> 21571 | Y30: =Statements!J45 -> 30035.673 | AC30: =AC28-AC29 -> 4079.5033 | AD30: =AD28-AD29 -> 4632.8759 | AE30: =AE28-AE29 -> 7397.519 | AF30: =AF28-AF29 -> 7820.5032
B32: Debt Assumptions
Q33: Balance Sheet | V33: Historical | Z33: Transaction Adjustments | AC33: Forecast
B34: Leverage ratio: | F34: =F13 -> 3 | H34: Debt Required: | L34: =L13 -> 211003.39 | V34: 44920 | W34: 45285 | X34: 45651 | Y34: 46016 | Z34: Debit | AA34: Credit | AB34: 46016 | AC34: 46381 | AD34: 46746 | AE34: 47112 | AF34: 47477
B35: Term Loan A (%): | F35: 0.5 | H35: Revolver: | L35: 10000
B36: Term Loan B (%): | F36: 0.25 | H36: Term Loan A : | L36: =$L$34*F35 -> 105501.7 | Q36: Assets
B37: Subordinated debt (%): | F37: 0.15 | H37: Term Loan B : | L37: =$L$34*F36 -> 52750.848 | Q37: Current assets:
B38: Mezzanine finance (%): | F38: 0.1 | H38: Subordinated debt : | L38: =$L$34*F37 -> 31650.509 | P38: * | Q38: Cash and cash equivalents | V38: =Statements!G59 -> 3523 | W38: =Statements!H59 -> 4893 | X38: =Statements!I59 -> 1698 | Y38: =Statements!J59 -> 2265.5068 | Z38: 0 | AA38: =F52 -> 265.50685 | AB38: =Y38+Z38-AA38 -> 2000 | AC38: =AC127 -> -29630.4 | AD38: =AD127 -> -24970.465 | AE38: =AE127 -> -20975.306 | AF38: =AF127 -> -17355.878
H39: Mezzanine finance : | L39: =$L$34*F38 -> 21100.339 | Q39: Investments | V39: =Statements!G60 -> 1746 | W39: =Statements!H60 -> 1281 | X39: =Statements!I60 -> 1106 | Y39: =Statements!J60 -> 1106 | Z39: 0 | AA39: 0 | AB39: =Y39+Z39-AA39 -> 1106 | AC39: =Statements!K60 -> 1106 | AD39: =Statements!L60 -> 1106 | AE39: =Statements!M60 -> 1106 | AF39: =Statements!N60 -> 1106
Q40: Receivables, net | V40: =Statements!G61 -> 25576 | W40: =Statements!H61 -> 21391 | X40: =Statements!I61 -> 24433 | Y40: =Statements!J61 -> 24560.923 | Z40: 0 | AA40: 0 | AB40: =Y40+Z40-AA40 -> 24560.923 | AC40: =Statements!K61 -> 25077.957 | AD40: =Statements!L61 -> 26076.42 | AE40: =Statements!M61 -> 27191.49 | AF40: =Statements!N61 -> 28519.935
B41: Interest rates (%) | H41: Principal repayment (%) | Q41: Inventories | V41: =Statements!G62 -> 5538 | W41: =Statements!H62 -> 2175 | X41: =Statements!I62 -> 1747 | Y41: =Statements!J62 -> 1726.622 | Z41: 0 | AA41: 0 | AB41: =Y41+Z41-AA41 -> 1726.622 | AC41: =Statements!K62 -> 1788.5656 | AD41: =Statements!L62 -> 1905.8029 | AE41: =Statements!M62 -> 2020.8026 | AF41: =Statements!N62 -> 2172.1241
B42: Revolver: | F42: SOFR + 150 | H42: Revolver: | L42: N/A | Q42: Assets held for sale | V42: =Statements!G63 -> 1403 | W42: =Statements!H63 -> 1455 | X42: =Statements!I63 -> 381 | Y42: =Statements!J63 -> 381 | Z42: 0 | AA42: 0 | AB42: =Y42+Z42-AA42 -> 381 | AC42: =Statements!K63 -> 381 | AD42: =Statements!L63 -> 381 | AE42: =Statements!M63 -> 381 | AF42: =Statements!N63 -> 381
B43: Term Loan A : | F43: SOFR + 300 | H43: Term Loan A : | L43: 0.1 | Q43: Prepaid and other current assets | V43: =Statements!G64 -> 12529 | W43: =Statements!H64 -> 12855 | X43: =Statements!I64 -> 10628 | Y43: =Statements!J64 -> 11921.591 | Z43: 0 | AA43: 0 | AB43: =Y43+Z43-AA43 -> 11921.591 | AC43: =Statements!K64 -> 11981.953 | AD43: =Statements!L64 -> 12153.023 | AE43: =Statements!M64 -> 12954.306 | AF43: =Statements!N64 -> 13501.838
...

Sheet Equity Report
H1: SEQUEIRA CAPITAL INVESTMENTS
B2: Date | E2: COUNTRY | SECTOR | EQUITY RESEARCH
B4: Company Name
B5: NSE: | BSE: | F5: s
B8: Model Date: | Last Historical Year: FY 25 | Forecast Horizon: FY 26-FY 30 | I8: Eldric Gregory Sequeira
I9: seqcapin@gmaco | 91+ 11111111111
I14: Recommendation
I15: Recommendation
I16: DCF fair value
I17: WACC
I18: Terminal Growth rate
I19: Upside / (Downside)
I21: Key Data - INFO
I22: CMP
I23: Market Cap
I24: Free float
I25: Shares outstanding
... I28: INR/US
