Workbook
Name BS: Statements!$B$58
Name CF: Statements!$B$107
Name days: Dashboard!$G$19
Name Debt: Schedule!$B$89
Name EF: Scenario!$B$27
Name Equity: Schedule!$B$102
Name IS: Statements!$B$20
Name OpEx: Scenario!$B$39
Name PPE: Schedule!$B$13
Name RE: Schedule!$B$102
Name RF: Scenario!$B$13
Name Seller_share_price: Merger_BS!$E$13
Name units: Dashboard!$G$12
Name WC: Schedule!$B$52

Sheet Dashboard
B2: Synopsys, INC.
B3: Dashboard
B4: ($ in Millions, Except Per Share Amounts in Dollars and Share Counts in Thousands)
B7: Model Assumption | F7: Units:
B9: Company Name | G9: =UPPER(B2) -> SYNOPSYS, INC. | M9: Cell Reference
B10: Ticker | G10: SNPS
B11: Valuation Date | F11: Date | G11: =TODAY() -> 46098 | L11: Hardcode | N11: Caution
B12: Units | F12: # | G12: 100 | L12: Calculation | N12: Assumptions
L13: Reference | N13: Notes
B14: Selected Scenario | G14: N/A | L14: (Except for Dashboard, and Cash flow statement)
B16: Model Start Date | F16: Date | G16: =Statements!I7 -> 45596
B17: Model End Date | F17: Date | G17: =Statements!N7 -> 47422
B18: No. of Years Projected | F18: Years | G18: =YEARFRAC(G16,G17,1) -> 4.9981752
B19: Days in an Year | F19: Days | G19: 360
C22: Table of Contents
C23: Particulars
B25: 1 | C25: Dashboard
B26: 2 | C26: Financials
B27: 3 | C27: Statements
B28: 4 | C28: Scenario
B29: 5 | C29: Assumptions
B30: 6 | C30: Schedule
B31: 7 | C31: Valuation
B32: 8 | C32: Beta
B33: 9 | C33: WACC
B34: 10 | C34: FCFF
B35: 11 | C35: Report
B36: 12 | C36: Ratio Analysis
B37: 13 | C37: Equity Report

Sheet Financials->

Sheet Statements
B2: =Dashboard!B2 -> Synopsys, INC.
B3: Financial statements
B4: =Dashboard!B4 -> ($ in Millions, Except Per Share Amounts in Dollars and Share Counts in Thousands)
B5: Active Scenario | D5: =Dashboard!G14 -> N/A
B6: Date | G6: Historicals | J6: Forecast | O6: CAGR | Q6: Notes
B7: Historicals / Forecast | G7: 44865 | H7: =EDATE(G7,12) -> 45230 | I7: =EDATE(H7,12) -> 45596 | J7: =EDATE(I7,12) -> 45961 | K7: =EDATE(J7,12) -> 46326 | L7: =EDATE(K7,12) -> 46691 | M7: =EDATE(L7,12) -> 47057 | N7: =EDATE(M7,12) -> 47422 | O7: FY 23- FY 25 | P7: FY 26 - FY 30
B9: <-Back to dashboard
B11: Go to -> | C11: Income statement | E11: Balance statement | G11: Cash flow statement
B15: Templete: | C15: Standard | E15: Source: | F15: Company Website
B16: Period type: | C16: Annual | E16: Decimals: | F16: None
B17: Currency: | C17: Reported
B18: Units: | C18: USD
A20: # | B20: Income statement | G20: 44865 | H20: 45230 | I20: 45596 | J20: 45961 | K20: 46326 | L20: 46691 | M20: 47057 | N20: 47422
B22: Revenue:
B23: Time-Based products | G23: 2657724 | H23: 3016256 | I23: 3224299 | J23: =Scenario!J15 -> 3489609 | K23: =Scenario!K15 -> 3782736.2 | L23: =Scenario!L15 -> 4119399.7 | M23: =Scenario!M15 -> 4494265 | N23: =Scenario!N15 -> 4916726
B24: Upfront products | G24: 1221240 | H24: 1400125 | I24: 1802222 | J24: =Scenario!J17 -> 2010602 | K24: =Scenario!K17 -> 2261927.2 | L24: =Scenario!L17 -> 2560501.6 | M24: =Scenario!M17 -> 2921532.4 | N24: =Scenario!N17 -> 3356840.7
B25: Total products revenue | G25: =SUM(G23:G24) -> 3878964 | H25: =SUM(H23:H24) -> 4416381 | I25: =SUM(I23:I24) -> 5026521 | J25: =SUM(J23:J24) -> 5500211 | K25: =SUM(K23:K24) -> 6044663.4 | L25: =SUM(L23:L24) -> 6679901.3 | M25: =SUM(M23:M24) -> 7415797.4 | N25: =SUM(N23:N24) -> 8273566.7 | O25: =_xlfn.RRI(2,G25,I25) -> 0.13835017 | P25: =_xlfn.RRI(4,J25,N25) -> 0.10746078
B26: Maintenance and service | G26: 736750 | H26: 901633 | I26: 1100915 | J26: =Scenario!J21 -> 1553967 | K26: =Scenario!K21 -> 1997543.9 | L26: =Scenario!L21 -> 2578829.2 | M26: =Scenario!M21 -> 3355056.8 | N26: =Scenario!N21 -> 4388414.3
B27: Total revenue | G27: =SUM(G25:G26) -> 4615714 | H27: =SUM(H25:H26) -> 5318014 | I27: =SUM(I25:I26) -> 6127436 | J27: =SUM(J25:J26) -> 7054178 | K27: =SUM(K25:K26) -> 8042207.3 | L27: =SUM(L25:L26) -> 9258730.5 | M27: =SUM(M25:M26) -> 10770854 | N27: =SUM(N25:N26) -> 12661981 | O27: =_xlfn.RRI(2,G27,I27) -> 0.15217898 | P27: =_xlfn.RRI(4,J27,N27) -> 0.15748084
B28: Cost of Revenue:
B29: Products | G29: 594007 | H29: 697686 | I29: 770238 | J29: =Scenario!J29 -> 867165 | K29: =Scenario!K29 -> 984050.61 | L29: =Scenario!L29 -> 1103652.2 | M29: =Scenario!M29 -> 1244246.8 | N29: =Scenario!N29 -> 1403394.7
B30: Maintenance and service | G30: 259332 | H30: 287876 | I30: 367055 | J30: =Scenario!J31 -> 444526 | K30: =Scenario!K31 -> 511204.9 | L30: =Scenario!L31 -> 592997.68 | M30: =Scenario!M31 -> 693807.29 | N30: =Scenario!N31 -> 818692.6
B31: Amortization of acquired intangible assets | G31: 44674 | H31: 45281 | I31: 107996 | J31: =Scenario!J33 -> 311858 | K31: =Scenario!K33 -> 316535.87 | L31: =Scenario!L33 -> 321283.91 | M31: =Scenario!M33 -> 326103.17 | N31: =Scenario!N33 -> 330994.71
B32: Total cost of revenue | G32: =SUM(G29:G31) -> 898013 | H32: =SUM(H29:H31) -> 1030843 | I32: =SUM(I29:I31) -> 1245289 | J32: =SUM(J29:J31) -> 1623549 | K32: =SUM(K29:K31) -> 1811791.4 | L32: =SUM(L29:L31) -> 2017933.8 | M32: =SUM(M29:M31) -> 2264157.3 | N32: =SUM(N29:N31) -> 2553082 | O32: =_xlfn.RRI(2,G32,I32) -> 0.17758906 | P32: =_xlfn.RRI(4,J32,N32) -> 0.11982418
B33: Gross margin | G33: =G27-G32 -> 3717701 | H33: =H27-H32 -> 4287171 | I33: =I27-I32 -> 4882147 | J33: =J27-J32 -> 5430629 | K33: =K27-K32 -> 6230416 | L33: =L27-L32 -> 7240796.7 | M33: =M27-M32 -> 8506697 | N33: =N27-N32 -> 10108899 | O33: =_xlfn.RRI(2,G33,I33) -> 0.14595667 | P33: =_xlfn.RRI(4,J33,N33) -> 0.16805537
B34: Operating expenses:
B35: Research and development | G35: 1589846 | H35: 1849935 | I35: 2082360 | J35: =Scenario!J41 -> 2269772.4 | K35: =Scenario!K41 -> 2474051.9 | L35: =Scenario!L41 -> 2696716.6 | M35: =Scenario!M41 -> 2939421.1 | N35: =Scenario!N41 -> 3203969
B36: Sales and marketing | G36: 642729 | H36: 724934 | I36: 859342 | J36: =Scenario!J43 -> 964181.72 | K36: =Scenario!K43 -> 1081811.9 | L36: =Scenario!L43 -> 1213792.9 | M36: =Scenario!M43 -> 1361875.7 | N36: =Scenario!N43 -> 1528024.5
B37: General and administrative | G37: 313554 | H37: 376677 | I37: 568496 | J37: =Scenario!J45 -> 632167.55 | K37: =Scenario!K45 -> 702970.32 | L37: =Scenario!L45 -> 781702.99 | M37: =Scenario!M45 -> 869253.73 | N37: =Scenario!N45 -> 966610.15
B38: Amortization of acquired intangible assets | G38: 11637 | H38: 9295 | I38: 16238 | J38: =Scenario!J47 -> 18267.75 | K38: =Scenario!K47 -> 20423.344 | L38: =Scenario!L47 -> 23119.226 | M38: =Scenario!M47 -> 26147.845 | N38: =Scenario!N47 -> 29024.107
B39: Restructuring charges | G39: 11221 | H39: 53091 | I39: 0 | J39: 0 | K39: 0 | L39: 0 | M39: 0 | N39: 0
B40: Total operating expenses | G40: =SUM(G35:G39) -> 2568987 | H40: =SUM(H35:H39) -> 3013932 | I40: =SUM(I35:I39) -> 3526436 | J40: =SUM(J35:J39) -> 3884389.4 | K40: =SUM(K35:K39) -> 4279257.5 | L40: =SUM(L35:L39) -> 4715331.8 | M40: =SUM(M35:M39) -> 5196698.3 | N40: =SUM(N35:N39) -> 5727627.8 | O40: =_xlfn.RRI(2,G40,I40) -> 0.17162074 | P40: =_xlfn.RRI(4,J40,N40) -> 0.10195283
B41: Operating income | G41: =G33-G40 -> 1148714 | H41: =H33-H40 -> 1273239 | I41: 1355711 | J41: =J33-J40 -> 1546239.6 | K41: =K33-K40 -> 1951158.5 | L41: =L33-L40 -> 2525465 | M41: =M33-M40 -> 3309998.6 | N41: =N33-N40 -> 4381271.2 | O41: =_xlfn.RRI(2,G41,I41) -> 0.086369597 | P41: =_xlfn.RRI(4,J41,N41) -> 0.29742075
B42: Interest expense | G42: =8545 -> 8545 | H42: -2703 | I42: -36829 | J42: =-Schedule!J99 -> -766.5525 | K42: =-Schedule!K99 -> -665.49 | L42: =-Schedule!L99 -> -578.865 | M42: =-Schedule!M99 -> -507.99 | N42: =-Schedule!N99 -> -443.6775
B43: Other income (expense), net | G43: =-1698-67516+10713+4694 -> -53807 | H43: 34934 | I43: 194976 | J43: =Assumptions!J16 -> 38655.989 | K43: =Assumptions!K16 -> 50730.121 | L43: =Assumptions!L16 -> 68187.554 | M43: =Assumptions!M16 -> 92679.961 | N43: =Assumptions!N16 -> 127056.87
B44: Income before income taxes | G44: =SUM(G41:G43) -> 1103452 | H44: =SUM(H41:H43) -> 1305470 | I44: =SUM(I41:I43) -> 1513858 | J44: =SUM(J41:J43) -> 1584129 | K44: =SUM(K41:K43) -> 2001223.1 | L44: =SUM(L41:L43) -> 2593073.7 | M44: =SUM(M41:M43) -> 3402170.6 | N44: =SUM(N41:N43) -> 4507884.4 | O44: =_xlfn.RRI(2,G44,I44) -> 0.17129381 | P44: =_xlfn.RRI(4,J44,N44) -> 0.2988098
B45: Provision for income taxes | G45: 139385 | H45: 90188 | I45: 99718 | J45: =Assumptions!J13 -> 55991 | K45: =Assumptions!K13 -> 320195.7 | L45: =Assumptions!L13 -> 414891.79 | M45: =Assumptions!M13 -> 544347.3 | N45: =Assumptions!N13 -> 721261.51
B46: Net income from continuing operations | G46: =G44-G45 -> 964067 | H46: =H44-H45 -> 1215282 | I46: =I44-I45 -> 1414140 | J46: =J44-J45 -> 1528138 | K46: =K44-K45 -> 1681027.4 | L46: =L44-L45 -> 2178181.9 | M46: =M44-M45 -> 2857823.3 | N46: =N44-N45 -> 3786622.9 | O46: =_xlfn.RRI(2,G46,I46) -> 0.21113511 | P46: =_xlfn.RRI(4,J46,N46) -> 0.25464936
B47: Income (loss) from discountinued operations | G47: 14369 | H47: 2843 | I47: 821670 | J47: 0 | K47: 0 | L47: 0 | M47: 0 | N47: 0
B48: Net income | G48: =SUM(G46:G47) -> 978436 | H48: =SUM(H46:H47) -> 1218125 | I48: =SUM(I46:I47) -> 2235810 | J48: =SUM(J46:J47) -> 1528138 | K48: =SUM(K46:K47) -> 1681027.4 | L48: =SUM(L46:L47) -> 2178181.9 | M48: =SUM(M46:M47) -> 2857823.3 | N48: =SUM(N46:N47) -> 3786622.9 | O48: =_xlfn.RRI(2,G48,I48) -> 0.51164995 | P48: =_xlfn.RRI(4,J48,N48) -> 0.25464936
...

Sheet Scenario
B2: =Dashboard!B2 -> Synopsys, INC.
B3: Scenario
B4: =Dashboard!B4 -> ($ in Millions, Except Per Share Amounts in Dollars and Share Counts in Thousands)
B5: Active Scenario | D5: =Dashboard!G14 -> N/A
B6: Date | G6: Historicals | J6: Forecast | O6: CAGR | Q6: Notes
B7: Actual / Forecast | G7: 44865 | H7: =EDATE(G7,12) -> 45230 | I7: =EDATE(H7,12) -> 45596 | J7: =EDATE(I7,12) -> 45961 | K7: =EDATE(J7,12) -> 46326 | L7: =EDATE(K7,12) -> 46691 | M7: =EDATE(L7,12) -> 47057 | N7: =EDATE(M7,12) -> 47422 | O7: FY 23- FY 25 | P7: FY 26 - FY 30
B9: <-Back to dashboard
B11: Go to -> | C11: Revenue forecast | E11: Expense forecast | G11: Operating Expenses
A13: # | B13: Revenue Forecast | G13: 44865 | H13: 45230 | I13: 45596 | J13: 45961 | K13: 46326 | L13: 46691 | M13: 47057 | N13: 47422
B15: Time-Based products | G15: =Statements!G23 -> 2657724 | H15: =Statements!H23 -> 3016256 | I15: =Statements!I23 -> 3224299 | J15: 3489609 | K15: =J15*(1+K16) -> 3782736.2 | L15: =K15*(1+L16) -> 4119399.7 | M15: =L15*(1+M16) -> 4494265 | N15: =M15*(1+N16) -> 4916726
B16: yoy Time-Based products growth (%) | H16: =H15/G15-1 -> 0.13490189 | I16: =I15/H15-1 -> 0.06897392 | J16: =J15/I15-1 -> 0.082284552 | K16: 0.084 | L16: 0.089 | M16: 0.091 | N16: 0.094
B17: Upfront products | G17: =Statements!G24 -> 1221240 | H17: =Statements!H24 -> 1400125 | I17: =Statements!I24 -> 1802222 | J17: 2010602 | K17: =J17*(1+K18) -> 2261927.2 | L17: =K17*(1+L18) -> 2560501.6 | M17: =L17*(1+M18) -> 2921532.4 | N17: =M17*(1+N18) -> 3356840.7
B18: yoy Upfront products growth (%) | H18: =H17/G17-1 -> 0.14647817 | I18: =I17/H17-1 -> 0.2871865 | J18: =J17/I17-1 -> 0.11562394 | K18: 0.125 | L18: 0.132 | M18: 0.141 | N18: 0.149
B19: Total products revenue | G19: =SUM(G15:G17) -> 3878964 | H19: =SUM(H15:H17) -> 4416381.1 | I19: =SUM(I15:I17) -> 5026521.1 | J19: =SUM(J15:J17) -> 5500211.1 | K19: =K15+K17 -> 6044663.4 | L19: =L15+L17 -> 6679901.3 | M19: =M15+M17 -> 7415797.4 | N19: =N15+N17 -> 8273566.7 | O19: =_xlfn.RRI(2,G19,I19) -> 0.13835018 | P19: =_xlfn.RRI(4,J19,N19) -> 0.10746078
B20: yoy Total products revenue growth (%) | H20: =H19/G19-1 -> 0.13854656 | I20: =I19/H19-1 -> 0.13815382 | J20: =J19/I19-1 -> 0.094238143 | K20: =K19/J19-1 -> 0.098987533 | L20: =L19/K19-1 -> 0.1050907 | M20: =M19/L19-1 -> 0.11016571 | N20: =N19/M19-1 -> 0.11566784
B21: Maintenance and service | G21: =Statements!G26 -> 736750 | H21: =Statements!H26 -> 901633 | I21: =Statements!I26 -> 1100915 | J21: 1553967 | K21: =J21*(1+K22) -> 1997543.9 | L21: =K21*(1+L22) -> 2578829.2 | M21: =L21*(1+M22) -> 3355056.8 | N21: =M21*(1+N22) -> 4388414.3
B22: yoy Maintenance and service growth (%) | H22: =H21/G21-1 -> 0.22379776 | I22: =I21/H21-1 -> 0.22102341 | J22: =J21/I21-1 -> 0.41152314 | K22: =AVERAGE(H22:J22) -> 0.2854481 | L22: 0.291 | M22: 0.301 | N22: 0.308
B23: Total revenue | G23: =SUM(G19:G21) -> 4615714 | H23: =SUM(H19:H21) -> 5318014.3 | I23: =SUM(I19:I21) -> 6127436.2 | J23: =SUM(J19:J21) -> 7054178.2 | K23: =K19+K21 -> 8042207.3 | L23: =L19+L21 -> 9258730.5 | M23: =M19+M21 -> 10770854 | N23: =N19+N21 -> 12661981 | O23: =_xlfn.RRI(2,G23,I23) -> 0.152179 | P23: =_xlfn.RRI(4,J23,N23) -> 0.15748083
B24: yoy Total revenue growth (%) | H24: =H23/G23-1 -> 0.1521542 | I24: =I23/H23-1 -> 0.15220379 | J24: =J23/I23-1 -> 0.15124465 | K24: =K23/J23-1 -> 0.14006297 | L24: =L23/K23-1 -> 0.15126733 | M24: =M23/L23-1 -> 0.16331869 | N24: =N23/M23-1 -> 0.17557816
A27: # | B27: Expenses forecast | G27: 44865 | H27: 45230 | I27: 45596 | J27: 45961 | K27: 46326 | L27: 46691 | M27: 47057 | N27: 47422
B29: Products | G29: =Statements!G29 -> 594007 | H29: =Statements!H29 -> 697686 | I29: =Statements!I29 -> 770238 | J29: 867165 | K29: =J29*(1+K30) -> 984050.61 | L29: =K29*(1+L30) -> 1103652.2 | M29: =L29*(1+M30) -> 1244246.8 | N29: =M29*(1+N30) -> 1403394.7
B30: yoy Products growth (%) | H30: =H29/G29-1 -> 0.17454171 | I30: =I29/H29-1 -> 0.10398947 | J30: =J29/I29-1 -> 0.12584032 | K30: =AVERAGE(H30:J30) -> 0.1347905 | L30: =AVERAGE(I30:K30) -> 0.1215401 | M30: =AVERAGE(J30:L30) -> 0.12739031 | N30: =AVERAGE(K30:M30) -> 0.12790697
B31: Maintenance and service | G31: =Statements!G30 -> 259332 | H31: =Statements!H30 -> 287876 | I31: =Statements!I30 -> 367055 | J31: 444526 | K31: =J31*(1+K32) -> 511204.9 | L31: =K31*(1+L32) -> 592997.68 | M31: =L31*(1+M32) -> 693807.29 | N31: =M31*(1+N32) -> 818692.6
B32: yoy Maintenance and service growth (%) | H32: =H31/G31-1 -> 0.1100674 | I32: =I31/H31-1 -> 0.27504551 | J32: =J31/I31-1 -> 0.21106101 | K32: 0.15 | L32: =K32+($N$32-$K$32)/3 -> 0.16 | M32: =L32+($N$32-$K$32)/3 -> 0.17 | N32: 0.18
B33: Amortization of acquired intangible assets | G33: =Statements!G31 -> 44674 | H33: =Statements!H31 -> 45281 | I33: =Statements!I31 -> 107996 | J33: 311858 | K33: =J33*(1+K34) -> 316535.87 | L33: =K33*(1+L34) -> 321283.91 | M33: =L33*(1+M34) -> 326103.17 | N33: =M33*(1+N34) -> 330994.71
B34: yoy Amortization of acquired intangible assets growth (%) | H34: =H33/G33-1 -> 0.013587321 | I34: =I33/H33-1 -> 1.385018 | J34: =J33/I33-1 -> 1.887681 | K34: 0.015 | L34: 0.015 | M34: 0.015 | N34: 0.015
B35: Total cost of revenue | G35: =Statements!G32 -> 898013 | H35: =Statements!H32 -> 1030843 | I35: =Statements!I32 -> 1245289 | J35: =J29+J31+J33 -> 1623549 | K35: =K29+K31+K33 -> 1811791.4 | L35: =L29+L31+L33 -> 2017933.8 | M35: =M29+M31+M33 -> 2264157.3 | N35: =N29+N31+N33 -> 2553082 | O35: =_xlfn.RRI(2,G35,I35) -> 0.17758906 | P35: =_xlfn.RRI(4,J35,N35) -> 0.11982418
B36: yoy Total cost of reveneue growth (%) | H36: =H35/G35-1 -> 0.14791545 | I36: =I35/H35-1 -> 0.20802974 | J36: =J35/I35-1 -> 0.30375278 | K36: =K35/J35-1 -> 0.11594499 | L36: =L35/K35-1 -> 0.11377824 | M36: =M35/L35-1 -> 0.12201761 | N36: =N35/M35-1 -> 0.12760805
A39: # | B39: Operating Expenses | G39: 44865 | H39: 45230 | I39: 45596 | J39: 45961 | K39: 46326 | L39: 46691 | M39: 47057 | N39: 47422
B41: Research and development | G41: =Statements!G35 -> 1589846 | H41: =Statements!H35 -> 1849935 | I41: =Statements!I35 -> 2082360 | J41: =I41*(1+J42) -> 2269772.4 | K41: =J41*(1+K42) -> 2474051.9 | L41: =K41*(1+L42) -> 2696716.6 | M41: =L41*(1+M42) -> 2939421.1 | N41: =M41*(1+N42) -> 3203969
B42: yoy R&D growth (%) | H42: =H41/G41-1 -> 0.16359383 | I42: =I41/H41-1 -> 0.12563955 | J42: 0.09 | K42: 0.09 | L42: 0.09 | M42: 0.09 | N42: 0.09
B43: Sales and marketing | G43: =Statements!G36 -> 642729 | H43: =Statements!H36 -> 724934 | I43: =Statements!I36 -> 859342 | J43: =I43*(1+J44) -> 964181.72 | K43: =J43*(1+K44) -> 1081811.9 | L43: =K43*(1+L44) -> 1213792.9 | M43: =L43*(1+M44) -> 1361875.7 | N43: =M43*(1+N44) -> 1528024.5
B44: yoy S&M growth (%) | H44: =H43/G43-1 -> 0.12789994 | I44: =I43/H43-1 -> 0.18540722 | J44: 0.122 | K44: 0.122 | L44: 0.122 | M44: 0.122 | N44: 0.122
B45: General and administrative | G45: =Statements!G37 -> 313554 | H45: =Statements!H37 -> 376677 | I45: =Statements!I37 -> 568496 | J45: =I45*(1+J46) -> 632167.55 | K45: =J45*(1+K46) -> 702970.32 | L45: =K45*(1+L46) -> 781702.99 | M45: =L45*(1+M46) -> 869253.73 | N45: =M45*(1+N46) -> 966610.15
B46: yoy G&M growth (%) | H46: =H45/G45-1 -> 0.20131461 | I46: =I45/H45-1 -> 0.50924001 | J46: 0.112 | K46: 0.112 | L46: 0.112 | M46: 0.112 | N46: 0.112
B47: Amortization of acquired intangible assets | G47: =Statements!G38 -> 11637 | H47: =Statements!H38 -> 9295 | I47: =Statements!I38 -> 16238 | J47: =I47*(1+J48) -> 18267.75 | K47: =J47*(1+K48) -> 20423.344 | L47: =K47*(1+L48) -> 23119.226 | M47: =L47*(1+M48) -> 26147.845 | N47: =M47*(1+N48) -> 29024.107
B48: yoy Amortization of acquired intangible assets growth (%) | H48: =H47/G47-1 -> -0.20125462 | I48: =I47/H47-1 -> 0.74696073 | J48: 0.125 | K48: 0.118 | L48: 0.132 | M48: 0.131 | N48: 0.11
B49: Restructuring charges | G49: =Statements!G39 -> 11221 | H49: =Statements!H39 -> 53091 | I49: =Statements!I39 -> 0 | J49: 0 | K49: =J49 -> 0 | L49: =K49 -> 0 | M49: =L49 -> 0 | N49: =M49 -> 0
B50: Total operating expenses | G50: =G41+G43+G45+G47+G49 -> 2568987 | H50: =H41+H43+H45+H47+H49 -> 3013932 | I50: =I41+I43+I45+I47+I49 -> 3526436 | J50: =J41+J43+J45+J47+J49 -> 3884389.4 | K50: =K41+K43+K45+K47+K49 -> 4279257.5 | L50: =L41+L43+L45+L47+L49 -> 4715331.8 | M50: =M41+M43+M45+M47+M49 -> 5196698.3 | N50: =N41+N43+N45+N47+N49 -> 5727627.8 | O50: =_xlfn.RRI(2,G50,I50) -> 0.17162074 | P50: =_xlfn.RRI(4,J50,N50) -> 0.10195283
B51: yoy Products growth (%) | H51: =H50/G50-1 -> 0.17319862 | I51: =I50/H50-1 -> 0.17004498 | J51: =J50/I50-1 -> 0.10150572 | K51: =K50/J50-1 -> 0.10165511 | L51: =L50/K50-1 -> 0.10190419 | M51: =M50/L50-1 -> 0.10208541 | N51: =N50/M50-1 -> 0.10216668
...

Sheet Assumptions
B2: =Dashboard!B2 -> Synopsys, INC.
B3: Assumptions
B4: =Dashboard!B4 -> ($ in Millions, Except Per Share Amounts in Dollars and Share Counts in Thousands)
B5: Active Scenario | D5: =Dashboard!G14 -> N/A
B6: Date | G6: Historicals | J6: Forecast | O6: CAGR | Q6: Notes
B7: Actual / Forecast | G7: 44865 | H7: =EDATE(G7,12) -> 45230 | I7: =EDATE(H7,12) -> 45596 | J7: =EDATE(I7,12) -> 45961 | K7: =EDATE(J7,12) -> 46326 | L7: =EDATE(K7,12) -> 46691 | M7: =EDATE(L7,12) -> 47057 | N7: =EDATE(M7,12) -> 47422 | O7: FY 23- FY 25 | P7: FY 26 - FY 30
B9: <-Back to dashboard
A11: # | B11: Assumptions | G11: 44865 | H11: 45230 | I11: 45596 | J11: 45961 | K11: 46326 | L11: 46691 | M11: 47057 | N11: 47422
B13: Provision for income taxes | G13: =Statements!G45 -> 139385 | H13: =Statements!H45 -> 90188 | I13: =Statements!I45 -> 99718 | J13: 55991 | K13: =K14*Statements!K44 -> 320195.7 | L13: =L14*Statements!L44 -> 414891.79 | M13: =M14*Statements!M44 -> 544347.3 | N13: =N14*Statements!N44 -> 721261.51
B14: Income taxes as a % of PBT | G14: =G13/Statements!G44 -> 0.12631723 | H14: =H13/Statements!H44 -> 0.069084697 | I14: =I13/Statements!I44 -> 0.065870115 | J14: 0.16 | K14: 0.16 | L14: 0.16 | M14: 0.16 | N14: 0.16
B16: Other income (expense), net | G16: =Statements!G43 -> -53807 | H16: =Statements!H43 -> 34934 | I16: =Statements!I43 -> 194976 | J16: =J17*Statements!J41 -> 38655.989 | K16: =K17*Statements!K41 -> 50730.121 | L16: =L17*Statements!L41 -> 68187.554 | M16: =M17*Statements!M41 -> 92679.961 | N16: =N17*Statements!N41 -> 127056.87
B17: Other income (expense), net as a % of EBIT | G17: =G16/Statements!G41 -> -0.046841076 | H17: =H16/Statements!H41 -> 0.027437111 | I17: =I16/Statements!I41 -> 0.14381826 | J17: 0.025 | K17: 0.026 | L17: 0.027 | M17: 0.028 | N17: 0.029
B19: Non-controlling interest | G19: =-Statements!G49 -> 6158 | H19: =-Statements!H49 -> 11763 | I19: =-Statements!I49 -> 27570 | J19: =Statements!J48*Assumptions!J20 -> 14405.993 | K19: =K20*Statements!K48 -> 15847.305 | L19: =L20*Statements!K48 -> 17164.154 | M19: =M20*Statements!L48 -> 22541.963 | N19: =N20*Statements!M48 -> 28159.422
B20: Non-controlling interest as a % of PAT | G20: =G19/Statements!G48 -> 0.0062937177 | H20: =H19/Statements!H48 -> 0.0096566444 | I20: =I19/Statements!I48 -> 0.012331101 | J20: =AVERAGE(G20:I20) -> 0.0094271545 | K20: =AVERAGE(G20:J20) -> 0.0094271545 | L20: =AVERAGE(H20:K20) -> 0.010210514 | M20: =AVERAGE(I20:L20) -> 0.010348981 | N20: =AVERAGE(J20:M20) -> 0.009853451
B22: Stock-based compensation | G22: 459029 | H22: 563292 | I22: 692316 | J22: =J23*Statements!J48 -> 632251.8 | K22: =K23*Statements!K48 -> 664462.11 | L22: =L23*Statements!L48 -> 812215.17 | M22: =M23*Statements!M48 -> 1125885.4 | N22: =N23*Statements!N48 -> 1466842.1
B23: Stock-based compensation as a % of PAT | G23: =G22/Statements!G48 -> 0.46914566 | H23: =H22/Statements!H48 -> 0.46242545 | I23: =I22/Statements!I48 -> 0.30964885 | J23: =AVERAGE(G23:I23) -> 0.41373999 | K23: =AVERAGE(H23:J23) -> 0.39527143 | L23: =AVERAGE(I23:K23) -> 0.37288676 | M23: =AVERAGE(J23:L23) -> 0.39396606 | N23: =AVERAGE(K23:M23) -> 0.38737475

Sheet Schedule
B2: =Dashboard!B2 -> Synopsys, INC.
B3: Schedule
B4: =Dashboard!B4 -> ($ in Millions, Except Per Share Amounts in Dollars and Share Counts in Thousands)
B5: Active Scenario | D5: =Dashboard!G14 -> N/A
B6: Date | G6: Historicals | J6: Forecast
B7: Actual / Forecast | G7: 44865 | H7: =EDATE(G7,12) -> 45230 | I7: =EDATE(H7,12) -> 45596 | J7: =EDATE(I7,12) -> 45961 | K7: =EDATE(J7,12) -> 46326 | L7: =EDATE(K7,12) -> 46691 | M7: =EDATE(L7,12) -> 47057 | N7: =EDATE(M7,12) -> 47422
B9: <-Back to dashboard
B11: Go to -> | C11: PPE and intangibles | E11: Working capital | G11: Debt Schedule | H11: Equity schedule
A13: # | B13: Property, plant, and equipment and Intangible schedule
B15: Property, plant and equipment
B17: Opening balance of Gross PP&E | G17: 1276745 | H17: =G19 -> 1349655 | I17: =H19 -> 1473283 | J17: =I19 -> 1492987 | K17: =J19 -> 1617795.2 | L17: =K19 -> 1753036.9 | M17: =L19 -> 1899584.3 | N17: =M19 -> 2058382.5
B18: Additons to PPE | J18: =J23 -> 124808.18 | K18: =K23 -> 135241.68 | L18: =L23 -> 146547.39 | M18: =M23 -> 158798.21 | N18: =N23 -> 172073.15
B19: Closing balance of Gross PP&E | G19: 1349655 | H19: 1473283 | I19: 1492987 | J19: =SUM(J17:J18) -> 1617795.2 | K19: =SUM(K17:K18) -> 1753036.9 | L19: =SUM(L17:L18) -> 1899584.3 | M19: =SUM(M17:M18) -> 2058382.5 | N19: =SUM(N17:N18) -> 2230455.6
B20: Accumulated depreciation | I20: -929981 | J20: =I20-J28 -> -1047677 | K20: =J20-K28 -> -1183431.9 | L20: =K20-L28 -> -1343142.5 | M20: =L20-M28 -> -1503879.8 | N20: =M20-N28 -> -1682023
B21: Closing balance of Net PP&E | J21: =SUM(J19:J20) -> 570118.2 | K21: =SUM(K19:K20) -> 569605.01 | L21: =SUM(L19:L20) -> 556441.71 | M21: =SUM(M19:M20) -> 554502.66 | N21: =SUM(N19:N20) -> 548432.59
B23: CapEx of PP&E | G23: 136589 | H23: 189618 | I23: 123161 | J23: =J24*J17 -> 124808.18 | K23: =K24*K17 -> 135241.68 | L23: =L24*L17 -> 146547.39 | M23: =M24*M17 -> 158798.21 | N23: =N24*N17 -> 172073.15
B24: CapEx as a % of Opening balance of PP&E | G24: =G23/G17 -> 0.10698221 | H24: =H23/H17 -> 0.14049368 | I24: =I23/I17 -> 0.083596295 | J24: =I24 -> 0.083596295 | K24: =J24 -> 0.083596295 | L24: =K24 -> 0.083596295 | M24: =L24 -> 0.083596295 | N24: =M24 -> 0.083596295
B26: Deprecaition and Amortization | G26: 228405 | H26: 247120 | I26: 295065 | J26: =J28+J39+J49 -> 226881.12 | K26: =K28+K39+K49 -> 237903.48 | L26: =L28+L39+L49 -> 272471.54 | M26: =M28+M39+M49 -> 268240.59 | N26: =N28+N39+N49 -> 290717.77
B28: Depreciation of PP&E | G28: 103900 | H28: 141400 | I28: 162900 | J28: =J29*J23 -> 117695.98 | K28: =K29*K23 -> 135754.87 | L28: =L29*L23 -> 159710.69 | M28: =M29*M23 -> 160737.26 | N28: =N29*N23 -> 178143.21
B29: Depreciation as a % of CapEx | G29: =G28/G23 -> 0.76067619 | H29: =H28/H23 -> 0.7457098 | I29: =I28/I23 -> 1.322659 | J29: =AVERAGE(G29:I29) -> 0.94301498 | K29: =AVERAGE(H29:J29) -> 1.0037946 | L29: =AVERAGE(I29:K29) -> 1.0898228 | M29: =AVERAGE(J29:L29) -> 1.0122108 | N29: =AVERAGE(K29:M29) -> 1.0352761
B31: Intangible assets
B33: Opening balance of Gross intangible assets | G33: 1598984 | H33: =G35 -> 1801997 | I33: =H35 -> 1378798 | J33: =I35 -> 1407794 | K33: =J35 -> 1497794 | L33: =K35 -> 1587794 | M33: =L35 -> 1677794 | N33: =M35 -> 1767794
B34: Additions to intangibles | J34: 90000 | K34: 90000 | L34: 90000 | M34: 90000 | N34: 90000
B35: Closing balance of Gross intangible asset | G35: 1801997 | H35: 1378798 | I35: 1407794 | J35: =SUM(J33:J34) -> 1497794 | K35: =SUM(K33:K34) -> 1587794 | L35: =SUM(L33:L34) -> 1677794 | M35: =SUM(M33:M34) -> 1767794 | N35: =SUM(N33:N34) -> 1857794
B36: Accumulated amortization | I36: -1212630 | J36: =I36-J39 -> -1259066 | K36: =J36-K39 -> -1295178 | L36: =K36-L39 -> -1326343 | M36: =L36-M39 -> -1351915 | N36: =M36-N39 -> -1374953
B37: Closing balance of Net intangible asset | J37: =SUM(J35:J36) -> 238728 | K37: =SUM(K35:K36) -> 292616 | L37: =SUM(L35:L36) -> 351451 | M37: =SUM(M35:M36) -> 415879 | N37: =SUM(N35:N36) -> 482841
B39: Amortisaiton of Intangible assets | G39: 49900 | H39: 52100 | I39: 48500 | J39: 46436 | K39: 36112 | L39: 31165 | M39: 25572 | N39: 23038
B40: Amortisaiton as a % of Closing balance of intangibles | G40: =G39/G35 -> 0.0276915 | H40: =H39/H35 -> 0.037786536 | I40: =I39/I35 -> 0.034451063 | J40: =J39/J35 -> 0.031002928 | K40: =K39/K35 -> 0.022743505 | L40: =L39/L35 -> 0.018574986 | M40: =M39/M35 -> 0.014465486 | N40: =N39/N35 -> 0.012400729
B42: Other non-current assets
B44: Opening balance of NCA | J44: =Statements!I75 -> 583700 | K44: =J47 -> 638706.8 | L44: =K47 -> 701930.82 | M44: =L47 -> 775697.23 | N44: =M47 -> 861152.47
B45: Additions (Disposal) of NCA | J45: =J47-J46-J44 -> 117755.94 | K45: =K47-K46-K44 -> 129260.63 | L45: =L47-L46-L44 -> 155362.26 | M45: =M47-M46-M44 -> 167386.57 | N45: =N47-N46-N44 -> 189144.2
B46: Less: Depreciation related to NCA | J46: =-J49 -> -62749.134 | K46: =-K49 -> -66036.608 | L46: =-L49 -> -81595.854 | M46: =-M49 -> -81931.335 | N46: =-N49 -> -89536.56
B47: Closing balance of NCA | J47: =Statements!J75 -> 638706.8 | K47: =Statements!K75 -> 701930.82 | L47: =Statements!L75 -> 775697.23 | M47: =Statements!M75 -> 861152.47 | N47: =Statements!N75 -> 960760.11
B49: Depreciation related to NCA | G49: =G26-G28-G39 -> 74605 | H49: =H26-H28-H39 -> 53620 | I49: =I26-I28-I39 -> 83665 | J49: =J50*J23 -> 62749.134 | K49: =K50*K23 -> 66036.608 | L49: =L50*L23 -> 81595.854 | M49: =M50*M23 -> 81931.335 | N49: =N50*N23 -> 89536.56
B50: Depreciation related to NCA as a % of CapEx | G50: =G49/G23 -> 0.54620065 | H50: =H49/H23 -> 0.28277906 | I50: =I49/I23 -> 0.67931407 | J50: =AVERAGE(G50:I50) -> 0.50276459 | K50: =AVERAGE(H50:J50) -> 0.48828591 | L50: =AVERAGE(I50:K50) -> 0.55678819 | M50: =AVERAGE(J50:L50) -> 0.51594623 | N50: =AVERAGE(K50:M50) -> 0.52034011
A52: # | B52: Working capital schedule
B54: Current assets
B56: Accounts receivables | G56: =Statements!G64 -> 796091 | H56: =Statements!H64 -> 856660 | I56: =Statements!I64 -> 934470 | J56: =J71*Statements!J$25/days -> 1022532.7 | K56: =K71*Statements!K$25/days -> 1123750.7 | L56: =L71*Statements!L$25/days -> 1241846.5 | M56: =M71*Statements!M$25/days -> 1378655.4 | N56: =N71*Statements!N$25/days -> 1538121.5
B57: Inventories | G57: =Statements!G65 -> 211927 | H57: =Statements!H65 -> 325590 | I57: =Statements!I65 -> 361849 | J57: =J72*Statements!J$25/days -> 395948.98 | K57: =K72*Statements!K$25/days -> 435143 | L57: =L72*Statements!L$25/days -> 480872.48 | M57: =M72*Statements!M$25/days -> 533848.14 | N57: =N72*Statements!N$25/days -> 595597.2
B58: Prepaid and other current assets | G58: =Statements!G66 -> 439130 | H58: =Statements!H66 -> 548115 | I58: =Statements!I66 -> 1122946 | J58: =J73*Statements!J$25/days -> 1228770.3 | K58: =K73*Statements!K$25/days -> 1350403.3 | L58: =L73*Statements!L$25/days -> 1492318.1 | M58: =M73*Statements!M$25/days -> 1656720.4 | N58: =N73*Statements!N$25/days -> 1848349.7
...

Sheet Valuation->
A1: \

Sheet Beta
B2: =Dashboard!B2 -> Synopsys, INC.
B3: Beta
B4: =Dashboard!B4 -> ($ in Millions, Except Per Share Amounts in Dollars and Share Counts in Thousands)
B6: <-Back to dashboard
B8: Go to -> | C8: WACC | D8: FCFF
B11: Synopsys | F11: NYSE | J11: Beta Drifting
B13: Date | C13: Price | D13: Returns | F13: Date | G13: Price | H13: Returns | J13: Calculated beta | L13: =SLOPE(D15:D263,H15:H263) -> 1.4107477
B14: 46087 | C14: 437.41 | F14: 46087 | G14: 22518.1
B15: 46086 | C15: 442.3 | D15: =C15/C14-1 -> 0.011179443 | F15: 46086 | G15: 22789.6 | H15: =G15/G14-1 -> 0.012056968 | J15: Levered beta | L15: =L13 -> 1.4107477
B16: 46085 | C16: 430.98 | D16: =C16/C15-1 -> -0.025593489 | F16: 46085 | G16: 23086.3 | H16: =G16/G15-1 -> 0.013019096 | J16: Raw beta weight | L16: 0.75
B17: 46084 | C17: 424.32 | D17: =C17/C16-1 -> -0.015453153 | F17: 46084 | G17: 22998.2 | H17: =G17/G16-1 -> -0.0038161161
B18: 46083 | C18: 424.66 | D18: =C18/C17-1 -> 0.00080128205 | F18: 46083 | G18: 23413.1 | H18: =G18/G17-1 -> 0.018040542 | J18: Market beta | L18: =SLOPE(H15:H263,H15:H263) -> 1
B19: 46080 | C19: 414 | D19: =C19/C18-1 -> -0.025102435 | F19: 46080 | G19: 23494.4 | H19: =G19/G18-1 -> 0.003472415 | J19: Raw beta weight | L19: 0.25
B20: 46079 | C20: 426 | D20: =C20/C19-1 -> 0.028985507 | F20: 46079 | G20: 23524.8 | H20: =G20/G19-1 -> 0.0012939254
B21: 46078 | C21: 449.17 | D21: =C21/C20-1 -> 0.054389671 | F21: 46078 | G21: 23452.7 | H21: =G21/G20-1 -> -0.0030648507 | J21: Adjusted beta | L21: =(L15*L16)+(L18*L19) -> 1.3080608
B22: 46077 | C22: 440.72 | D22: =C22/C21-1 -> -0.018812476 | F22: 46077 | G22: 23383.8 | H22: =G22/G21-1 -> -0.0029378281
B23: 46076 | C23: 420.82 | D23: =C23/C22-1 -> -0.045153385 | F23: 46076 | G23: 23214.9 | H23: =G23/G22-1 -> -0.0072229492 | J23: Total years | L23: =YEARFRAC(F263,F14,1) -> 0.9890411
B24: 46073 | C24: 439.94 | D24: =C24/C23-1 -> 0.045435103 | F24: 46073 | G24: 23452.6 | H24: =G24/G23-1 -> 0.010239114 | J24: Market returns (%) | L24: =AVERAGE(H15:H263) -> -0.00059129142
B25: 46072 | C25: 442.44 | D25: =C25/C24-1 -> 0.0056825931 | F25: 46072 | G25: 23358.3 | H25: =G25/G24-1 -> -0.0040208762
B26: 46071 | C26: 442.31 | D26: =C26/C25-1 -> -0.00029382515 | F26: 46071 | G26: 23387.5 | H26: =G26/G25-1 -> 0.001250091
B27: 46070 | C27: 421.95 | D27: =C27/C26-1 -> -0.046031064 | F27: 46070 | G27: 23300.8 | H27: =G27/G26-1 -> -0.0037071085
B28: 46066 | C28: 437.09 | D28: =C28/C27-1 -> 0.035881029 | F28: 46066 | G28: 23326.1 | H28: =G28/G27-1 -> 0.0010857996
B29: 46065 | C29: 423.35 | D29: =C29/C28-1 -> -0.031435174 | F29: 46065 | G29: 23188.8 | H29: =G29/G28-1 -> -0.0058861104
B30: 46064 | C30: 438.21 | D30: =C30/C29-1 -> 0.03510098 | F30: 46064 | G30: 23479.7 | H30: =G30/G29-1 -> 0.012544849
B31: 46063 | C31: 437.45 | D31: =C31/C30-1 -> -0.0017343283 | F31: 46063 | G31: 23398.1 | H31: =G31/G30-1 -> -0.0034753425
B32: 46062 | C32: 438.9 | D32: =C32/C31-1 -> 0.0033146645 | F32: 46062 | G32: 23340.7 | H32: =G32/G31-1 -> -0.0024531906
B33: 46059 | C33: 426.88 | D33: =C33/C32-1 -> -0.027386648 | F33: 46059 | G33: 23252.8 | H33: =G33/G32-1 -> -0.0037659539
B34: 46058 | C34: 410.44 | D34: =C34/C33-1 -> -0.038511994 | F34: 46058 | G34: 22733.3 | H34: =G34/G33-1 -> -0.022341395
B35: 46057 | C35: 418.98 | D35: =C35/C34-1 -> 0.020806939 | F35: 46057 | G35: 22975.6 | H35: =G35/G34-1 -> 0.010658373
B36: 46056 | C36: 419.14 | D36: =C36/C35-1 -> 0.0003818798 | F36: 46056 | G36: 22881.2 | H36: =G36/G35-1 -> -0.0041087066
... B263: 45726 | C263: 429.85 | D263: =C263/C262-1 -> -0.0019271849 | F263: 45726 | G263: 19202.4 | H263: =G263/G262-1 -> 0.0078888941

Sheet WACC
B2: =Dashboard!B2 -> Synopsys, INC.
B3: WACC
B4: =Dashboard!B4 -> ($ in Millions, Except Per Share Amounts in Dollars and Share Counts in Thousands)
B6: <-Back to dashboard
B8: Go to -> | C8: Beta | D8: FCFF
C10: Cost of Equity | H10: Capital Structure
C11: Risk free rate | E11: 0.0421 | H11: Market Cap | I11: =Public_Comps!F31 -> 808118.9
C12: Equity risk premium | E12: 0.0446 | H12: Debt | I12: =Statements!I89+Statements!I82+Statements!I87 -> 684457
C13: Country risk premium | E13: 0.0023 | H13: Total Capital | I13: =I11+I12 -> 1492575.9
C14: Levered beta | E14: =Beta!L21 -> 1.3080608
C15: Cost of equity | E15: =E11+(E12*E14)+E13 -> 0.10273951
C17: Cost of Debt | H17: WACC
C18: (Using credit rating) | H18: Cost of Equity | I18: =E15*(I11/I13) -> 0.055625807
C19: Risk free rate | E19: 0.0421 | H19: Cost of Debt | I19: =E23*(I12/I13) -> 0.021468616
C20: Risk premium | E20: 0.0111 | H20: WACC | I20: =I18+I19 -> 0.077094423
C21: Pre-tax cost of debt | E21: =E19+E20 -> 0.0532
C22: Tax Rate | E22: 0.12
C23: Post-tax cost of debt | E23: =E21*(1-E22) -> 0.046816

Sheet FCFF
B2: =Dashboard!B2 -> Synopsys, INC.
B3: FCFF
B4: =Dashboard!B4 -> ($ in Millions, Except Per Share Amounts in Dollars and Share Counts in Thousands)
B6: <-Back to dashboard
B8: Go to -> | C8: Beta | D8: WACC
B10: Valuation parameters
B12: Valuation as on specified date | E12: 45596
B13: Date of year ending | E13: 45657
B14: Marginal Tax Rate (%) | E14: 0.25
B15: WACC (%) | E15: =WACC!I20 -> 0.077094423
B16: Terminal Growth Rate (%) | E16: 0.02
B19: Free Cash Flow to Firm | G19: =Statements!J7 -> 45961 | H19: =Statements!K7 -> 46326 | I19: =Statements!L7 -> 46691 | J19: =Statements!M7 -> 47057 | K19: =Statements!N7 -> 47422
B21: EBIT | G21: =Statements!J41 -> 1546239.6 | H21: =Statements!K41 -> 1951158.5 | I21: =Statements!L41 -> 2525465 | J21: =Statements!M41 -> 3309998.6 | K21: =Statements!N41 -> 4381271.2
B22: Tax rate (%) | G22: =$E$14 -> 0.25 | H22: =$E$14 -> 0.25 | I22: =$E$14 -> 0.25 | J22: =$E$14 -> 0.25 | K22: =$E$14 -> 0.25
B23: Less: Income taxes | G23: =G21*G22 -> 386559.89 | H23: =H21*H22 -> 487789.62 | I23: =I21*I22 -> 631366.24 | J23: =J21*J22 -> 827499.66 | K23: =K21*K22 -> 1095317.8
B24: NOPAT | G24: =G21-G23 -> 1159679.7 | H24: =H21-H23 -> 1463368.9 | I24: =I21-I23 -> 1894098.7 | J24: =J21-J23 -> 2482499 | K24: =K21-K23 -> 3285953.4
B25: Add: Depreciation and Amortisation | G25: =Statements!J112 -> 226881.12 | H25: =Statements!K112 -> 237903.48 | I25: =Statements!L112 -> 272471.54 | J25: =Statements!M112 -> 268240.59 | K25: =Statements!N112 -> 290717.77
B26: Add: Share-based compensation | G26: =Statements!J113 -> 632251.8 | H26: =Statements!K113 -> 664462.11 | I26: =Statements!L113 -> 812215.17 | J26: =Statements!M113 -> 1125885.4 | K26: =Statements!N113 -> 1466842.1
B27: Add/Less: Change in Working capital | G27: =Schedule!J67 -> -125457.27 | H27: =Schedule!K67 -> 86152.227 | I27: =Schedule!L67 -> 113121.58 | J27: =Schedule!M67 -> 124116.85 | K27: =Schedule!N67 -> 142874.57
B28: Less: Capital Expenditure | G28: =-Schedule!J23 -> -124808.18 | H28: =-Schedule!K23 -> -135241.68 | I28: =-Schedule!L23 -> -146547.39 | J28: =-Schedule!M23 -> -158798.21 | K28: =-Schedule!N23 -> -172073.15
B29: FCFF | G29: =SUM(G24:G28) -> 1768547.1 | H29: =SUM(H24:H28) -> 2316645 | I29: =SUM(I24:I28) -> 2945359.6 | J29: =SUM(J24:J28) -> 3841943.6 | K29: =SUM(K24:K28) -> 5014314.7
B31: Discount Factor | G31: =(E13-E12)/365 -> 0.16712329 | H31: =G31+1 -> 1.1671233 | I31: =H31+1 -> 2.1671233 | J31: =I31+1 -> 3.1671233 | K31: =J31+1 -> 4.1671233
B32: P.V of FCFF | G32: =G29/(1+$E$15)^G31 -> 1746732 | H32: =H29/(1+$E$15)^H31 -> 2124297.6 | I32: =I29/(1+$E$15)^I31 -> 2507497 | J32: =J29/(1+$E$15)^J31 -> 3036681.9 | K32: =K29/(1+$E$15)^K31 -> 3679646.7
B35: Price Target
B37: Terminal value of FCFF: | E37: =K29*(1+E16)/(E15-E16) -> 89581446
B38: NPV of Explicit cash flows: | E38: =SUM(G32:K32) -> 13094855
B39: NPV of Terminal value: | E39: =E37/(1+E15)^K31 -> 65737412
B40: Enterprise value: | E40: =E38+E39 -> 78832267
B41: Less: Debt | E41: =-(Statements!I89+Statements!I82+Statements!I87) -> -684457
B42: Add: Cash | E42: =Statements!I62 -> 3896532
B43: Add: Investments | E43: =Statements!H63 -> 151639
B44: Implied Equity Value: | E44: =SUM(E40:E43) -> 82195981
B45: No. of outstanding shares: | E45: 165700
B46: Implied Share Price: | E46: =E44/E45 -> 496.05299
B47: Current Share Price: | E47: 487.7
B48: (As on valuation date)
B49: Premium/Discount | E49: =IF(E47>E46,"Premium","Discount") -> Discount
B50: % Premium/Discount | E50: =E47/E46-1 -> -0.016838916
B52: Synopsys, INC. - Net present value sensitivity - Terminal growth rate
D53: WACC
...

Sheet Public_Comps
B2: =Dashboard!B2 -> Synopsys, INC.
B3: Comparable Companies
B6: <-Back to dashboard
B8: Comparable Companies - US-Based Other Software Companies with Over $1 Billion Revenue
B9: ($ in Millions, Except Per Share Amounts in Dollars and Share Counts in Thousands)
B11: Operating Statistics | D11: Market Data | J11: Financials | M11: Valuation
B12: Company Name | C12: Ticker
D13: Share Price | E13: Shares Outstanding | F13: Equity Value | G13: Cash | H13: Debt | I13: Enterprise Value | J13: Revenue | K13: EBITDA | L13: Net Income | M13: EV/Revenue | N13: EV/EBITDA | O13: P/E
B15: Cadence Design Systems, INC. | C15: CDNS | D15: 299.84 | E15: 276000 | F15: =D15/units*E15 -> 827558.4 | G15: 489.2 | H15: 2670 | I15: =F15+G15+H15 -> 830717.6 | J15: 530000 | K15: 191000 | L15: 111000 | M15: =I15/J15 -> 1.5673917 | N15: =I15/K15 -> 4.3493068 | O15: =D15/(L15/E15*units) -> 7.4554811
B16: ARM Holdings | C16: ARM | D16: 120.62 | E16: 106000 | F16: =D16/units*E16 -> 127857.2 | G16: 3080 | H16: 461 | I16: =F16+G16+H16 -> 131398.2 | J16: 467000 | K16: 108000 | L16: 80100 | M16: =I16/J16 -> 0.2813666 | N16: =I16/K16 -> 1.21665 | O16: =D16/(L16/E16*units) -> 1.5962197
B17: Keysight Technologies, Inc. | C17: KEYS | D17: 272.43 | E17: 171500 | F17: =D17/units*E17 -> 467217.45 | G17: 594 | H17: 2770 | I17: =F17+G17+H17 -> 470581.45 | J17: 568000 | K17: 129000 | L17: 96200 | M17: =I17/J17 -> 0.82848847 | N17: =I17/K17 -> 3.6479182 | O17: =D17/(L17/E17*units) -> 4.8567302
B18: Autodesk, Inc. | C18: ADSK | D18: 260.99 | E18: 21100 | F18: =D18/units*E18 -> 55068.89 | G18: 239 | H18: 2730 | I18: =F18+G18+H18 -> 58037.89 | J18: 721000 | K18: 191000 | L18: 112000 | M18: =I18/J18 -> 0.08049638 | N18: =I18/K18 -> 0.3038633 | O18: =D18/(L18/E18*units) -> 0.49168652
B19: ANSYS, Inc. | C19: ANSS | D19: 374.3 | E19: 879200 | F19: =D19/units*E19 -> 3290845.6 | G19: 967.65 | H19: 860.91 | I19: =F19+G19+H19 -> 3292674.2 | J19: 258000 | K19: 87404 | L19: 59278 | M19: =I19/J19 -> 12.762303 | N19: =I19/K19 -> 37.671893 | O19: =D19/(L19/E19*units) -> 55.515463
B21: Maximum | M21: =MAX(M15:M19) -> 12.762303 | N21: =MAX(N15:N19) -> 37.671893 | O21: =MAX(O15:O19) -> 55.515463
B22: 75% Percentile | M22: =QUARTILE(M15:M19,3) -> 1.5673917 | N22: =QUARTILE(N15:N19,3) -> 4.3493068 | O22: =QUARTILE(O15:O19,3) -> 7.4554811
B23: Median | M23: =MEDIAN(M15:M19) -> 0.82848847 | N23: =MEDIAN(N15:N19) -> 3.6479182 | O23: =MEDIAN(O15:O19) -> 4.8567302
B24: 25% Percentile | M24: =QUARTILE(M15:M19,1) -> 0.2813666 | N24: =QUARTILE(N15:N19,1) -> 1.21665 | O24: =QUARTILE(O15:O19,1) -> 1.5962197
B25: Minimum | M25: {=MIN(M15:M19)} -> 0.08049638 | N25: {=MIN(N15:N19)} -> 0.3038633 | O25: {=MIN(O15:O19)} -> 0.49168652
B27: Valuation for Synopsys, INC. | D27: Market Data | J27: Financials | M27: Valuation
B28: Company Name | C28: Ticker
D29: Share Price | E29: Shares Outstanding | F29: Equity Value | G29: Cash | H29: Debt | I29: Enterprise Value | J29: Revenue | K29: EBITDA | L29: Net Income | M29: EV/Revenue | N29: EV/EBITDA | O29: P/E
B31: Synopsys, INC. | D31: =FCFF!E47 -> 487.7 | E31: 165700 | F31: =D31/units*E31 -> 808118.9 | G31: =Statements!I62 -> 3896532 | H31: =Statements!I89 -> 15601 | I31: =F31+G31+H31 -> 4720251.9 | J31: =Statements!I27 -> 6127436 | K31: =Ratio_Analysis!G15 -> 2343092 | L31: =Statements!I48 -> 2235810
B33: Implied Enterprise Value | M33: =M23*J31 -> 5076510.1 | N33: =N23*K31 -> 8547408 | O33: =O34+O36+O35 -> 14770859
B34: Cash | M34: =$G$31 -> 3896532 | N34: =$G$31 -> 3896532 | O34: =$G$31 -> 3896532
B35: Net Debt | M35: =$H$31 -> 15601 | N35: =$H$31 -> 15601 | O35: =$H$31 -> 15601
B36: Implied Market Value | M36: =M33+M34+M35 -> 8988643.1 | N36: =N33+N34+N35 -> 12459541 | O36: =O23*L31 -> 10858726
B37: Shares Outstanding | M37: =$E$31 -> 165700 | N37: =$E$31 -> 165700 | O37: =$E$31 -> 165700
B38: Implied Value per Share | M38: =M36/M37*10000 -> 542464.88 | N38: =N36/N37*10000 -> 751933.67 | O38: =O36/O37*10000 -> 655324.45
M39: =IF($D$31>M$38,"Over valued","Under Valued") -> Under Valued | N39: =IF($D$31>N$38,"Over valued","Under Valued") -> Under Valued | O39: =IF($D$31>O$38,"Over valued","Under Valued") -> Under Valued
K41: Low | L41: 25th Point | M41: Median | N41: 75th Point | O41: High
J42: Company Comps
J43: EV/Revenue | K43: 265864.18 | L43: 340144.16 | M43: 542464.88 | N43: 815704.61 | O43: 4955481.4
J44: EV/EBITDA | K44: 279065.34 | L44: 408138.56 | M44: 751933.67 | N44: 851114 | O44: 5563116.8
J45: P/E | K45: 66343.852 | L45: 215379.84 | M45: 655324.45 | N45: 1005977 | O45: 7490768.1

Sheet Val_Sum
B2: =Dashboard!B2 -> Synopsys, INC.
B3: Valutaion Summary
B6: <-Back to dashboard
B8: Comparable Companies - US-Based Other Software Companies with Over $1 Billion Revenue
B9: ($ in Millions, Except Per Share Amounts in Dollars and Share Counts in Thousands)
B11: Valuation Summary (As on 31/12/2024) | C11: Low | D11: 25th Point / Close | E11: Median | F11: 75th Point / Open | G11: High
B13: Company Comps
B14: EV/Revenue | C14: 265.86 | D14: 340.14 | E14: 542.46 | F14: 815.7 | G14: 4955.48
B15: EV/EBITDA | C15: 279.06 | D15: 408.13 | E15: 751.93 | F15: 851.11 | G15: 5563.11
B16: P/E | C16: 66.34 | D16: 215.37 | E16: 655.32 | F16: 1005.97 | G16: 7490.76
B17: DCF | C17: 619.48706 | D17: 619.48706 | E17: 619.48706 | F17: 619.48706 | G17: 619.48706
B18: 52W H/L | C18: 365.74 | D18: 485.36 | E18: 487.7 | F18: 487.7 | G18: 651.73
B19: Terminal Growth Rate 1%-5% - WACC 6% - 10% | C19: 616.41295 | D19: 599.66414 | E19: 583.54886 | F19: 568.03754 | G19: 553.1022

Sheet Ratio_Analysis
B2: =Dashboard!B2 -> Synopsys, INC.
B3: Ratio Analysis
B4: =Dashboard!B4 -> ($ in Millions, Except Per Share Amounts in Dollars and Share Counts in Thousands)
B5: Date | E5: =Statements!G7 -> 44865 | F5: =EDATE(E5,12) -> 45230 | G5: =EDATE(F5,12) -> 45596 | H5: =EDATE(G5,12) -> 45961 | I5: =EDATE(H5,12) -> 46326 | J5: =EDATE(I5,12) -> 46691 | K5: =EDATE(J5,12) -> 47057 | L5: =EDATE(K5,12) -> 47422
B7: <-Back to dashboard
B9: Go to -> | C9: Stock Report
A11: # | B11: Ratio Analysis | E11: 44865 | F11: 45230 | G11: 45596 | H11: 45961 | I11: 46326 | J11: 46691 | K11: 47057 | L11: 47422
B13: 1. Profitability Ratio
B14: Absolute Earnings ($) | E14: 44865 | F14: 45230 | G14: 45596 | H14: 45961 | I14: 46326 | J14: 46691 | K14: 47057 | L14: 47422
B15: EBITDA | E15: =Statements!G41+Assumptions!G22+Schedule!G26 -> 1836148 | F15: =Statements!H41+Assumptions!H22+Schedule!H26 -> 2083651 | G15: =Statements!I41+Assumptions!I22+Schedule!I26 -> 2343092 | H15: =Statements!J41+Assumptions!J22+Schedule!J26 -> 2405372.5 | I15: =Statements!K41+Assumptions!K22+Schedule!K26 -> 2853524.1 | J15: =Statements!L41+Assumptions!L22+Schedule!L26 -> 3610151.7 | K15: =Statements!M41+Assumptions!M22+Schedule!M26 -> 4704124.6 | L15: =Statements!N41+Assumptions!N22+Schedule!N26 -> 6138831.1
B16: EBIT | E16: =Statements!G41 -> 1148714 | F16: =Statements!H41 -> 1273239 | G16: =Statements!I41 -> 1355711 | H16: =Statements!J41 -> 1546239.6 | I16: =Statements!K41 -> 1951158.5 | J16: =Statements!L41 -> 2525465 | K16: =Statements!M41 -> 3309998.6 | L16: =Statements!N41 -> 4381271.2
B17: Effective Tax Rate | E17: =Statements!G45/Statements!G44 -> 0.12631723 | F17: =Statements!H45/Statements!H44 -> 0.069084697 | G17: =Statements!I45/Statements!I44 -> 0.065870115 | H17: =Statements!J45/Statements!J44 -> 0.035344975 | I17: =Statements!K45/Statements!K44 -> 0.16 | J17: =Statements!L45/Statements!L44 -> 0.16 | K17: =Statements!M45/Statements!M44 -> 0.16 | L17: =Statements!N45/Statements!N44 -> 0.16
B18: NOPAT | E18: =E16*(1-E17) -> 1003611.6 | F18: =F16*(1-F17) -> 1185277.7 | G18: =G16*(1-G17) -> 1266410.2 | H18: =H16*(1-H17) -> 1491587.8 | I18: =I16*(1-I17) -> 1638973.1 | J18: =J16*(1-J17) -> 2121390.6 | K18: =K16*(1-K17) -> 2780398.8 | L18: =L16*(1-L17) -> 3680267.8
B19: PAT | E19: =Statements!G48 -> 978436 | F19: =Statements!H48 -> 1218125 | G19: =Statements!I48 -> 2235810 | H19: =Statements!J48 -> 1528138 | I19: =Statements!K48 -> 1681027.4 | J19: =Statements!L48 -> 2178181.9 | K19: =Statements!M48 -> 2857823.3 | L19: =Statements!N48 -> 3786622.9
B21: Margin Analysis (%) | E21: 44865 | F21: 45230 | G21: 45596 | H21: 45961 | I21: 46326 | J21: 46691 | K21: 47057 | L21: 47422
B22: Operating profit margin | E22: =Statements!G33/Statements!G27 -> 0.8054444 | F22: =Statements!H33/Statements!H27 -> 0.80616016 | G22: =Statements!I33/Statements!I27 -> 0.79676834 | H22: =Statements!J33/Statements!J27 -> 0.76984576 | I22: =Statements!K33/Statements!K27 -> 0.77471466 | J22: =Statements!L33/Statements!L27 -> 0.7820507 | K22: =Statements!M33/Statements!M27 -> 0.78978851 | L22: =Statements!N33/Statements!N27 -> 0.79836631
B23: EBITDA margin | E23: =E15/Statements!G$27 -> 0.39780368 | F23: =F15/Statements!H$27 -> 0.39180999 | G23: =G15/Statements!I$27 -> 0.38239355 | H23: =H15/Statements!J$27 -> 0.34098551 | I23: =I15/Statements!K$27 -> 0.35481852 | J23: =J15/Statements!L$27 -> 0.38991865 | K23: =K15/Statements!M$27 -> 0.43674573 | L23: =L15/Statements!N$27 -> 0.48482391
B24: EBIT margin | E24: =E16/Statements!G$27 -> 0.24887027 | F24: =F16/Statements!H$27 -> 0.23942002 | G24: =G16/Statements!I$27 -> 0.22125258 | H24: =H16/Statements!J$27 -> 0.21919486 | I24: =I16/Statements!K$27 -> 0.2426148 | J24: =J16/Statements!L$27 -> 0.27276579 | K24: =K16/Statements!M$27 -> 0.30731069 | L24: =L16/Statements!N$27 -> 0.34601784
B25: Net profit margin | E25: =E19/Statements!G$27 -> 0.21197934 | F25: =F19/Statements!H$27 -> 0.22905637 | G25: =G19/Statements!I$27 -> 0.36488508 | H25: =H19/Statements!J$27 -> 0.21662879 | I25: =I19/Statements!K$27 -> 0.20902563 | J25: =J19/Statements!L$27 -> 0.23525708 | K25: =K19/Statements!M$27 -> 0.26532931 | L25: =L19/Statements!N$27 -> 0.29905454
B27: Return Ratios | E27: 44865 | F27: 45230 | G27: 45596 | H27: 45961 | I27: 46326 | J27: 46691 | K27: 47057 | L27: 47422
B28: Return on Equity (ROE) | E28: =Statements!G48/Statements!G100 -> 0.17739028 | F28: =Statements!H48/Statements!H100 -> 0.19815584 | G28: =Statements!I48/Statements!I100 -> 0.24868025 | H28: =Statements!J48/Statements!J100 -> 0.13686251 | I28: =Statements!K48/Statements!K100 -> 0.12427352 | J28: =Statements!L48/Statements!L100 -> 0.13173641 | K28: =Statements!M48/Statements!M100 -> 0.13913015 | L28: =Statements!N48/Statements!N100 -> 0.14664175
B29: Return on Assets (ROA) | E29: =Statements!G48/Statements!G77 -> 0.10388904 | F29: =Statements!H48/Statements!H77 -> 0.11788537 | G29: =Statements!I48/Statements!I77 -> 0.17101767 | H29: =Statements!J48/Statements!J77 -> 0.096760854 | I29: =Statements!K48/Statements!K77 -> 0.090616473 | J29: =Statements!L48/Statements!L77 -> 0.098959235 | K29: =Statements!M48/Statements!M77 -> 0.10765611 | L29: =Statements!N48/Statements!N77 -> 0.11671291
B30: Return on Capital Employed (ROCE) | E30: =Statements!G41/(Statements!G77-Statements!G85) -> 0.17290566 | F30: =Statements!H41/(Statements!H77-Statements!H85) -> 0.17328449 | G30: =Statements!I41/(Statements!I77-Statements!I85) -> 0.13006367 | H30: =Statements!J41/(Statements!J77-Statements!J85) -> 0.12215303 | I30: =Statements!K41/(Statements!K77-Statements!K85) -> 0.12930439 | J30: =Statements!L41/(Statements!L77-Statements!L85) -> 0.13890653 | K30: =Statements!M41/(Statements!M77-Statements!M85) -> 0.14854922 | L30: =Statements!N41/(Statements!N77-Statements!N85) -> 0.15832436
B32: Dupoint Analysis (%) | E32: 44865 | F32: 45230 | G32: 45596 | H32: 45961 | I32: 46326 | J32: 46691 | K32: 47057 | L32: 47422
B33: Profit Margin | E33: =E25 -> 0.21197934 | F33: =F25 -> 0.22905637 | G33: =G25 -> 0.36488508 | H33: =H25 -> 0.21662879 | I33: =I25 -> 0.20902563 | J33: =J25 -> 0.23525708 | K33: =K25 -> 0.26532931 | L33: =L25 -> 0.29905454
B34: Asset Turnover | E34: =E49 -> 0.4900904 | F34: =F49 -> 0.51465659 | G34: =G49 -> 0.46868914 | H34: =H49 -> 0.44666665 | I34: =I49 -> 0.43351849 | J34: =J49 -> 0.42064297 | K34: =K49 -> 0.40574527 | L34: =L49 -> 0.39027299
B35: Financial Leverage | E35: =Statements!G77/Statements!G100 -> 1.7074976 | F35: =Statements!H77/Statements!H100 -> 1.6809197 | G35: =Statements!I77/Statements!I100 -> 1.4541202 | H35: =Statements!J77/Statements!J100 -> 1.4144409 | I35: =Statements!K77/Statements!K100 -> 1.3714231 | J35: =Statements!L77/Statements!L100 -> 1.3312189 | K35: =Statements!M77/Statements!M100 -> 1.2923572 | L35: =Statements!N77/Statements!N100 -> 1.2564312
B36: Dupont ROE | E36: =E33*E34*E35 -> 0.17739028 | F36: =F33*F34*F35 -> 0.19815584 | G36: =G33*G34*G35 -> 0.24868025 | H36: =H33*H34*H35 -> 0.13686251 | I36: =I33*I34*I35 -> 0.12427352 | J36: =J33*J34*J35 -> 0.13173641 | K36: =K33*K34*K35 -> 0.13913015 | L36: =L33*L34*L35 -> 0.14664175
B38: 2. Leverage Ratios
B39: Solvency (Ratios) | E39: 44865 | F39: 45230 | G39: 45596 | H39: 45961 | I39: 46326 | J39: 46691 | K39: 47057 | L39: 47422
B40: Debt / Equity | E40: =Statements!G89/Statements!G100 -> 0.0037753876 | F40: =Statements!H89/Statements!H100 -> 0.0029407995 | G40: =Statements!I89/Statements!I100 -> 0.0017352371 | H40: =Statements!J89/Statements!J100 -> 0.0012181275 | I40: =Statements!K89/Statements!K100 -> 0.00086871765 | J40: =Statements!L89/Statements!L100 -> 0.00062300432 | K40: =Statements!M89/Statements!M100 -> 0.00044063852 | L40: =Statements!N89/Statements!N100 -> 0.00030403987
B41: Debt / Assets | E41: =Statements!G89/Statements!G77 -> 0.0022110647 | F41: =Statements!H89/Statements!H77 -> 0.0017495181 | G41: =Statements!I89/Statements!I77 -> 0.0011933245 | H41: =Statements!J89/Statements!J77 -> 0.0008612078 | I41: =Statements!K89/Statements!K77 -> 0.00063344248 | J41: =Statements!L89/Statements!L77 -> 0.00046799539 | K41: =Statements!M89/Statements!M77 -> 0.00034095722 | L41: =Statements!N89/Statements!N77 -> 0.00024198688
B42: Debt / EBITDA | E42: =Statements!G89/Ratio_Analysis!E15 -> 0.011341134 | F42: =Statements!H89/Ratio_Analysis!F15 -> 0.0086761171 | G42: =Statements!I89/Ratio_Analysis!G15 -> 0.006658296 | H42: =Statements!J89/Ratio_Analysis!H15 -> 0.0056544257 | I42: =Statements!K89/Ratio_Analysis!I15 -> 0.0041180658 | J42: =Statements!L89/Ratio_Analysis!J15 -> 0.0028533427 | K42: =Statements!M89/Ratio_Analysis!K15 -> 0.0019240562 | L42: =Statements!N89/Ratio_Analysis!L15 -> 0.001278908
B44: 3. Efficency Ratios | E44: 44865 | F44: 45230 | G44: 45596 | H44: 45961 | I44: 46326 | J44: 46691 | K44: 47057 | L44: 47422
B45: Receivables Turnover | E45: =Statements!G$27/Statements!G64 -> 5.7979728 | F45: =Statements!H$27/Statements!H64 -> 6.2078468 | G45: =Statements!I$27/Statements!I64 -> 6.5571244 | H45: =Statements!J$27/Statements!J64 -> 6.8987309 | I45: =Statements!K$27/Statements!K64 -> 7.1565759 | J45: =Statements!L$27/Statements!L64 -> 7.4556161 | K45: =Statements!M$27/Statements!M64 -> 7.8125791 | L45: =Statements!N$27/Statements!N64 -> 8.2321073
B46: Inventory Turnover | E46: =Statements!G$27/Statements!G65 -> 21.779735 | F46: =Statements!H$27/Statements!H65 -> 16.333468 | G46: =Statements!I$27/Statements!I65 -> 16.933682 | H46: =Statements!J$27/Statements!J65 -> 17.815876 | I46: =Statements!K$27/Statements!K65 -> 18.481758 | J46: =Statements!L$27/Statements!L65 -> 19.254025 | K46: =Statements!M$27/Statements!M65 -> 20.175877 | L46: =Statements!N$27/Statements!N65 -> 21.259302
B47: Trade Payable Turnover | E47: =Statements!G32/Statements!G81 -> 1.1094757 | F47: =Statements!H32/Statements!H81 -> 0.9725723 | G47: =Statements!I32/Statements!I81 -> 1.070211 | H47: =Statements!J32/Statements!J81 -> 1.070211 | I47: =Statements!K32/Statements!K81 -> 1.070211 | J47: =Statements!L32/Statements!L81 -> 1.070211 | K47: =Statements!M32/Statements!M81 -> 1.070211 | L47: =Statements!N32/Statements!N81 -> 1.070211
B49: Total Asset Turnover | E49: =Statements!G27/Statements!G77 -> 0.4900904 | F49: =Statements!H27/Statements!H77 -> 0.51465659 | G49: =Statements!I27/Statements!I77 -> 0.46868914 | H49: =Statements!J27/Statements!J77 -> 0.44666665 | I49: =Statements!K27/Statements!K77 -> 0.43351849 | J49: =Statements!L27/Statements!L77 -> 0.42064297 | K49: =Statements!M27/Statements!M77 -> 0.40574527 | L49: =Statements!N27/Statements!N77 -> 0.39027299
B50: Fixed Asset Turnover | E50: =Statements!G27/Statements!G70 -> 9.5504118 | F50: =Statements!H27/Statements!H70 -> 9.6719828 | G50: =Statements!I27/Statements!I70 -> 10.883429 | H50: =Statements!J27/Statements!J70 -> 12.373185 | I50: =Statements!K27/Statements!K70 -> 14.11892 | J50: =Statements!L27/Statements!L70 -> 16.639174 | K50: =Statements!M27/Statements!M70 -> 19.424351 | L50: =Statements!N27/Statements!N70 -> 23.087579
B52: 4. Valuation Ratios
...

Sheet M&A
A1: \

Sheet Merger_Model
B2: =Dashboard!B2 -> Synopsys, INC.
B3: Merger Model
B4: =Dashboard!B4 -> ($ in Millions, Except Per Share Amounts in Dollars and Share Counts in Thousands)
B6: <-Back to dashboard
B8: Merger Model - Synopsys, INC. and ANSYS
A10: # | B10: Transaction Summary
B12: Per Share Purchase Price: | F12: 393.3 | H12: Equity Purchase Price: | K12: 35000
B13: % Cash: | F13: =K13/K12 -> 0.39142857 | H13: Cash Used: | K13: 13700
B14: % Debt: | F14: =K14/K12 -> 0.12285714 | H14: Debt Issued: | K14: =L17+L18 -> 4300
B15: % Stock: | F15: =100%-F14-F13 -> 0.48571429 | H15: New Shares Issued: | K15: =F15*K12/F40*units -> 2987.7502 | L15: =K12*F15 -> 17000
B16: Foregone Cash Interest Rate: | F16: 0.038 | H16: Term loan interest rate/Size
H17: Tranche 1: | K17: SOFR+0.875% | L17: =Merger_BS!D77 -> 1450
B18: Revenue synergy % | F18: 0.1 | H18: Tranche 2: | K18: SOFR+1.000% | L18: =Merger_BS!F77 -> 2850
B19: Cost synergies % OpEx | F19: 0.5 | H19: SOFR rate: | K19: 0.043
B20: Revenue synergy COGS % | F20: 0.25 | H20: (As on 31/12/2024)
A22: # | B22: Goodwill Creation & Balance Sheet Adjustments
B24: Goodwill calculation: | H24: Fixed asset write up:
B25: Equity purchase price | F25: =K12 -> 35000 | H25: PP&E write-up % | K25: 0.1
B26: Less: Seller bookvalue | F26: =-Merger_BS!I68 -> -60864.4 | H26: PP&E write-up amount | K26: =K25*Merger_BS!I40 -> 89.646
B27: Add: Write-off of existing goodwill | F27: =Merger_BS!I42 -> 37781.28 | H27: Depreciation period (Years) | K27: 8
B28: Total allocable purchase premium: | F28: =SUM(F25:F27) -> 11916.88
H29: Inangible asset write up:
B30: Less: Write-off of PP&E | F30: =-K26 -> -89.646 | H30: Purchase price to allocate | K30: =F28 -> 11916.88
B31: Less: Write-off of Intangibles | F31: =-K32 -> -2383.376 | H31: % Allocated to intangibles | K31: 0.2
B32: Less: Write-off of Deferred TL | F32: =-Merger_BS!I57 -> -558.63 | H32: Intangibles write-up amount | K32: =K30*K31 -> 2383.376
B33: Add: New deferred tax liability | F33: =K35 -> 445.14396 | H33: Amortisation period (Years) | K33: 5
B34: Total Goodwill created: | F34: =F28+F30+F31+F32+F33 -> 9330.372
H35: New deferred tax liabilities | K35: =(K26+K32)*F44 -> 445.14396
A37: # | B37: Buyer - Financial Profile | G37: # | H37: Seller - Financial Profile
B39: Buyer Name: | F39: Synopsys, INC. | H39: Seller Name: | K39: =Merger_BS!E12 -> ANSYS, INC.
B40: Share Price: | F40: 568.99 | H40: Share Price: | K40: =Seller_share_price -> 344.5
B41: Diluted Shares Outstanding: | F41: 165700 | H41: Diluted Shares Outstanding: | K41: =Merger_BS!F19 -> 87522.54
B42: Diluted Equity Value: | F42: =F41/units*F40 -> 942816.43 | H42: Diluted Equity Value: | K42: =Merger_BS!F20 -> 301515.15
B43: Enterprise Value: | F43: =Public_Comps!I31 -> 4720251.9 | H43: Enterprise Value: | K43: =Merger_BS!F26 -> 302236.15
B44: Tax Rate: | F44: 0.18 | H44: Tax Rate: | K44: =Merger_BS!I14 -> 0.21
A47: # | B47: Buyer - Income Statement | H47: Seller - Income Statement
E48: FY 2024 A | F48: FY 2025 E | J48: FY 2024 A | K48: FY 2025 E
B49: Revenue | E49: =Statements!I27 -> 6127436 | F49: =Statements!J27 -> 7054178 | H49: Revenue | J49: 2544809 | K49: 2840000
B50: COGS | E50: =Statements!I32 -> 1245289 | F50: =Statements!J32 -> 1623549 | H50: COGS | J50: 279819 | K50: =J50*(1+0.08) -> 302204.52
B51: Gross Profit | E51: =E49-E50 -> 4882147 | F51: =F49-F50 -> 5430629 | H51: Gross Profit | J51: =J49-J50 -> 2264990 | K51: =K49-K50 -> 2537795.5
...

Sheet Merger_BS
B2: =Dashboard!B2 -> Synopsys, INC.
B3: Merger Balance Sheet
B4: =Dashboard!B4 -> ($ in Millions, Except Per Share Amounts in Dollars and Share Counts in Thousands)
B6: <-Back to dashboard
B8: Merger Model - Synopsys, INC. and ANSYS, INC.
B10: Diluted Share & Enterprise Value Calculations - Seller
B12: Company Name: | E12: ANSYS, INC. | M12: Options Calculations - Current Price
B13: Share Price: | E13: 344.5
B14: Offer Price Per Share: | E14: =Merger_Model!F12 -> 393.3 | H14: Tax Rate: | I14: 0.21 | M14: Name | N14: Number | O14: Exercise Price | P14: Dilution
M15: A | N15: 100 | O15: 94.6 | P15: =IF(O15>Seller_share_price,0,N15-N15*O15/Seller_share_price) -> 72.539913
B16: Current Share Price | H16: Purchase Price
B17: Basic Shares Outstanding: | F17: 87450 | H17: Basic Shares Outstanding; | K17: =F17 -> 87450 | M17: Options Calculations - Purchase Price
B18: Basic Equity Value: | F18: =F17/units*Seller_share_price -> 301265.25 | H18: Basic Equity Value: | K18: =K17/units*E14 -> 343940.85
B19: Diluted Shares Outstanding: | F19: =F17+P15 -> 87522.54 | H19: Diluted Shares Outstanding: | K19: =K17+P20 -> 87525.947 | M19: Name | N19: Number | O19: Exercise Price | P19: Dilution
B20: Diluted Equity Value: | F20: =F19/units*Seller_share_price -> 301515.15 | H20: Diluted Equity Value: | K20: =K19/units*E14 -> 344239.55 | M20: A | N20: 100 | O20: 94.6 | P20: =IF(O15>O20,0,N20-N20*O20/E14) -> 75.947114
B21: Less: Cash & Investments | F21: 86020.1 | H21: Less: Cash & Investments | K21: 86020.1
B22: Add: Debt | F22: 75389.1 | H22: Add: Debt | K22: 75389.1
B23: Add: Minority Interest | F23: 0 | H23: Add: Minority Interests | K23: 0
B24: Add: Preferred Stock | F24: 0 | H24: Add: Preferred Stock | K24: 0
B25: Add: Other Liabilities | F25: 11352 | H25: Add: Other liabilities | K25: 11352
B26: Enterprise Value: | F26: =F20-F21+F22+F23+F24+F25 -> 302236.15 | H26: Enterprise Value: | K26: =K20-K21+K22+K23+K24+K25 -> 344960.55
B29: Balance Sheets - Buyer, Seller & Combined
B30: (As on 31 December, 2024)
G31: Buyer | I31: Seller | K31: Adjustments | M31: Pro-Forma Combined
B32: Assets
B33: Current Assets:
B34: Cash & Short-term investments | G34: 40504.01 | I34: 14975.17 | K34: =-Merger_Model!K13 -> -13700 | M34: =G34+I34+K34 -> 41779.18
B35: Accounts receivables | G35: 9344.7 | I35: 10228.5 | K35: 0 | M35: =G35+I35+K35 -> 19573.2
B36: Inventories | G36: 3618.49 | I36: 0 | K36: 0 | M36: =G36+I36+K36 -> 3618.49
B37: Other current assets | G37: 11229.46 | I37: 3111.26 | K37: 0 | M37: =G37+I37+K37 -> 14340.72
B38: Total Current assets | G38: 64696.66 | I38: 28314.93 | K38: =SUM(K34:K37) -> -13700 | M38: =SUM(M34:M37) -> 79311.59
B40: Property, plant and equipment | G40: 5630.06 | I40: 896.46 | K40: =Merger_Model!K26 -> 89.646 | M40: =G40+I40+K40 -> 6616.166
B41: Operating lease right of use assets | G41: 5659.17 | I41: 1051.22 | K41: 0 | M41: =G41+I41+K41 -> 6710.39
B42: Goodwill | G42: 34488.5 | I42: 37781.28 | K42: =-Merger_Model!F27+Merger_Model!F34 -> -28450.908 | M42: =G42+I42+K42 -> 43818.872
B43: Intangible assets | G43: 1951.64 | I43: 7162.44 | K43: =Merger_Model!K32 -> 2383.376 | M43: =G43+I43+K43 -> 11497.456
B44: Deferred income taxes | G44: 12472.58 | I44: 2224.65 | K44: 0 | M44: =G44+I44+K44 -> 14697.23
B45: Other long term assets | G45: 5837 | I45: 3083.33 | K45: 0 | M45: =G45+I45+K45 -> 8920.33
B46: Total Assets | G46: 130735.61 | I46: 80514.31 | K46: =SUM(K40:K45)+K38 -> -39677.886 | M46: =SUM(M40:M45)+M38 -> 171572.03
B48: Stockholders' Equity & Liabilities
B49: Current liabilities:
...

Sheet Report
A1: \

Sheet Equity Report
H1: SEQUEIRA CAPITAL INVESTMENTS
