Workbook

Sheet Co-variance
B2: 1. Historical Stock Data | Q2: 2. Calculate Returns | S2: (Yt/Yt-1)-1 | Y2: 3. Assumption of Investment amount and weights | AH2: 6. Calculate VaR using the Variance-Covariance method
B4: Date | C4: HUL | D4: Titan | E4: ICICI | F4: TCS | G4: MAHM | Q4: Date | R4: HUL | S4: Titan | T4: ICICI | U4: TCS | V4: MAHM | Y4: Portfolio | Z4: HUL | AA4: Titan | AB4: ICICI | AC4: TCS | AD4: MAHM | AH4: VaR using the Variance-Covariance method
B5: 46086 | C5: 2255 | D5: 4275.2 | E5: 1357.6 | F5: 2578.8 | G5: 3348 | Q5: 46086 | Y5: Weights | Z5: 0.15 | AA5: 0.25 | AB5: 0.3 | AC5: 0.2 | AD5: 0.1 | AH5: Mean | AI5: =$AC$11 -> -0.00019499081 | AJ5: =$AC$11 -> -0.00019499081 | AK5: =$AC$11 -> -0.00019499081
B6: 46085 | C6: 2261.3 | D6: 4204.4 | E6: 1365.4 | F6: 2587.8 | G6: 3264.3 | Q6: 46085 | R6: =C6/C5-1 -> 0.0027937916 | S6: =D6/D5-1 -> -0.016560629 | T6: =E6/E5-1 -> 0.0057454331 | U6: =F6/F5-1 -> 0.0034899953 | V6: =G6/G5-1 -> -0.025 | Y6: Investment Amt (INR) | AA6: 10000000 | AH6: Std Dev. | AI6: =$AD$25 -> 0.0075902673 | AJ6: =$AD$25 -> 0.0075902673 | AK6: =$AD$25 -> 0.0075902673
B7: 46083 | C7: 2320.6 | D7: 4270.3 | E7: 1374 | F7: 2613.5 | G7: 3334.3 | Q7: 46083 | R7: =C7/C6-1 -> 0.026223854 | S7: =D7/D6-1 -> 0.015674056 | T7: =E7/E6-1 -> 0.0062985206 | U7: =F7/F6-1 -> 0.0099312157 | V7: =G7/G6-1 -> 0.021444107 | Y7: Stock Value | Z7: =Z5*$AA$6 -> 1500000 | AA7: =AA5*$AA$6 -> 2500000 | AB7: =AB5*$AA$6 -> 3000000 | AC7: =AC5*$AA$6 -> 2000000 | AD7: =AD5*$AA$6 -> 1000000 | AE7: =_xlfn.FORMULATEXT(AD7) -> =AD5*$AA$6 | AH7: CI | AI7: 0.99 | AJ7: 0.95 | AK7: 0.9
B8: 46080 | C8: 2338.1 | D8: 4327.5 | E8: 1378.9 | F8: 2637.4 | G8: 3397.4 | Q8: 46080 | R8: =C8/C7-1 -> 0.0075411532 | S8: =D8/D7-1 -> 0.013394843 | T8: =E8/E7-1 -> 0.00356623 | U8: =F8/F7-1 -> 0.0091448249 | V8: =G8/G7-1 -> 0.018924512 | AH8: Alpha | AI8: =1-AI7 -> 0.01 | AJ8: =1-AJ7 -> 0.05 | AK8: =1-AK7 -> 0.1
B9: 46079 | C9: 2383.3 | D9: 4342.6 | E9: 1404.9 | F9: 2647.7 | G9: 3484.6 | Q9: 46079 | R9: =C9/C8-1 -> 0.019331936 | S9: =D9/D8-1 -> 0.0034893125 | T9: =E9/E8-1 -> 0.01885561 | U9: =F9/F8-1 -> 0.0039053613 | V9: =G9/G8-1 -> 0.025666686 | Y9: 4. Calculate portfolio mean return | AH9: Z-value | AI9: =_xlfn.NORM.S.INV(AI8) -> -2.3263479 | AJ9: =_xlfn.NORM.S.INV(AJ8) -> -1.6448536 | AK9: =_xlfn.NORM.S.INV(AK8) -> -1.2815516
B10: 46078 | C10: 2374.9 | D10: 4325 | E10: 1400.5 | F10: 2629.3 | G10: 3491.3 | Q10: 46078 | R10: =C10/C9-1 -> -0.0035245248 | S10: =D10/D9-1 -> -0.0040528716 | T10: =E10/E9-1 -> -0.0031318955 | U10: =F10/F9-1 -> -0.0069494278 | V10: =G10/G9-1 -> 0.0019227458 | Y10: =_xlfn.FORMULATEXT(Z13) -> =(R6*$Z$5+S6*$AA$5+T6*$AB$5+U6*$AC$5+V6*$AD$5) | AH10: Portfolio Value | AI10: =$AA$6 -> 10000000 | AJ10: =$AA$6 -> 10000000 | AK10: =$AA$6 -> 10000000
B11: 46077 | C11: 2358.6 | D11: 4294.5 | E11: 1384.8 | F11: 2573.7 | G11: 3433.2 | Q11: 46077 | R11: =C11/C10-1 -> -0.0068634469 | S11: =D11/D10-1 -> -0.0070520231 | T11: =E11/E10-1 -> -0.011210282 | U11: =F11/F10-1 -> -0.021146313 | V11: =G11/G10-1 -> -0.016641366 | Y11: Date | Z11: Return | AB11: Portfolio Mean | AC11: =AVERAGE(Z13:Z258) -> -0.00019499081 | AD11: =_xlfn.FORMULATEXT(AC11) -> =AVERAGE(Z13:Z258) | AH11: 1-Day VaR | AI11: =(AI5-(AI7*AI6))*AI10 -> -77093.554 | AJ11: =(AJ5-(AJ7*AJ6))*AJ10 -> -74057.447 | AK11: =(AK5-(AK7*AK6))*AK10 -> -70262.314 | AL11: =_xlfn.FORMULATEXT(AK11) -> =(AK5-(AK7*AK6))*AK10
B12: 46076 | C12: 2345.4 | D12: 4272.7 | E12: 1399.4 | F12: 2676.3 | G12: 3447.1 | Q12: 46076 | R12: =C12/C11-1 -> -0.0055965403 | S12: =D12/D11-1 -> -0.0050762603 | T12: =E12/E11-1 -> 0.010543039 | U12: =F12/F11-1 -> 0.039864786 | V12: =G12/G11-1 -> 0.0040487009 | Y12: 46086
B13: 46073 | C13: 2314.5 | D13: 4236.4 | E13: 1394.5 | F13: 2686.2 | G13: 3412.8 | Q13: 46073 | R13: =C13/C12-1 -> -0.013174725 | S13: =D13/D12-1 -> -0.0084957989 | T13: =E13/E12-1 -> -0.0035015006 | U13: =F13/F12-1 -> 0.0036991369 | V13: =G13/G12-1 -> -0.0099503931 | Y13: 46085 | Z13: =(R6*$Z$5+S6*$AA$5+T6*$AB$5+U6*$AC$5+V6*$AD$5) -> -0.0037994594
B14: 46072 | C14: 2279.3 | D14: 4198.2 | E14: 1388.8 | F14: 2677.9 | G14: 3431.8 | Q14: 46072 | R14: =C14/C13-1 -> -0.015208468 | S14: =D14/D13-1 -> -0.00901709 | T14: =E14/E13-1 -> -0.0040874866 | U14: =F14/F13-1 -> -0.0030898667 | V14: =G14/G13-1 -> 0.0055672761 | Y14: 46083 | Z14: =(R7*$Z$5+S7*$AA$5+T7*$AB$5+U7*$AC$5+V7*$AD$5) -> 0.013872302 | AB14: 5. Calculate portfolio standard deviation
B15: 46071 | C15: 2323.5 | D15: 4248.6 | E15: 1408.2 | F15: 2694.9 | G15: 3530.5 | Q15: 46071 | R15: =C15/C14-1 -> 0.019391919 | S15: =D15/D14-1 -> 0.012005145 | T15: =E15/E14-1 -> 0.013968894 | U15: =F15/F14-1 -> 0.006348258 | V15: =G15/G14-1 -> 0.028760417 | Y15: 46080 | Z15: =(R8*$Z$5+S8*$AA$5+T8*$AB$5+U8*$AC$5+V8*$AD$5) -> 0.009271169 | AI15: *The VaR value of INR 77,093.6 represents the estimated maximum loss in
B16: 46070 | C16: 2312.3 | D16: 4236.4 | E16: 1407.5 | F16: 2717.4 | G16: 3489.2 | Q16: 46070 | R16: =C16/C15-1 -> -0.0048203142 | S16: =D16/D15-1 -> -0.0028715342 | T16: =E16/E15-1 -> -0.00049708848 | U16: =F16/F15-1 -> 0.0083491039 | V16: =G16/G15-1 -> -0.01169806 | Y16: 46079 | Z16: =(R9*$Z$5+S9*$AA$5+T9*$AB$5+U9*$AC$5+V9*$AD$5) -> 0.012776542 | AC16: HUL | AD16: Titan | AE16: ICICI | AF16: TCS | AG16: MAHM | AI16: Rupees that you could expect to incur on your portfolio or investment
B17: 46069 | C17: 2319 | D17: 4181.1 | E17: 1411.6 | F17: 2706.6 | G17: 3509.7 | Q17: 46069 | R17: =C17/C16-1 -> 0.0028975479 | S17: =D17/D16-1 -> -0.013053536 | T17: =E17/E16-1 -> 0.0029129663 | U17: =F17/F16-1 -> -0.0039743873 | V17: =G17/G16-1 -> 0.0058752723 | Y17: 46078 | Z17: =(R10*$Z$5+S10*$AA$5+T10*$AB$5+U10*$AC$5+V10*$AD$5) -> -0.0036790762 | AB17: HUL | AC17: =VARP('Co-variance'!$R$7:$R$251) -> 0.00013483651 | AD17: 2.399836e-05 | AE17: 2.3513467e-05 | AF17: 2.6025084e-05 | AG17: 4.1381978e-05 | AI17: during a single day, under normal market conditions.
B18: 46066 | C18: 2305.2 | D18: 4179.2 | E18: 1414.6 | F18: 2692.2 | G18: 3533.4 | Q18: 46066 | R18: =C18/C17-1 -> -0.0059508409 | S18: =D18/D17-1 -> -0.00045442587 | T18: =E18/E17-1 -> 0.0021252479 | U18: =F18/F17-1 -> -0.0053203281 | V18: =G18/G17-1 -> 0.0067527139 | Y18: 46077 | Z18: =(R11*$Z$5+S11*$AA$5+T11*$AB$5+U11*$AC$5+V11*$AD$5) -> -0.012049007 | AB18: Titan | AC18: 2.399836e-05 | AD18: =VARP('Co-variance'!$S$7:$S$251) -> 0.00015384301 | AE18: 2.4523274e-05 | AF18: 3.2454481e-05 | AG18: 5.8843218e-05
B19: 46065 | C19: 2409.7 | D19: 4275.8 | E19: 1430 | F19: 2750.1 | G19: 3593.1 | Q19: 46065 | R19: =C19/C18-1 -> 0.045332292 | S19: =D19/D18-1 -> 0.023114472 | T19: =E19/E18-1 -> 0.01088647 | U19: =F19/F18-1 -> 0.021506575 | V19: =G19/G18-1 -> 0.016895908 | Y19: 46076 | Z19: =(R12*$Z$5+S12*$AA$5+T12*$AB$5+U12*$AC$5+V12*$AD$5) -> 0.0094321928 | AB19: ICICI | AC19: 2.3513467e-05 | AD19: 2.4523274e-05 | AE19: =VARP('Co-variance'!$T$7:$T$251) -> 0.00011333758 | AF19: 2.4770775e-05 | AG19: 5.8906482e-05
B20: 46064 | C20: 2462.9 | D20: 4249.1 | E20: 1406.1 | F20: 2909.8 | G20: 3674.9 | Q20: 46064 | R20: =C20/C19-1 -> 0.022077437 | S20: =D20/D19-1 -> -0.0062444455 | T20: =E20/E19-1 -> -0.016713287 | U20: =F20/F19-1 -> 0.058070616 | V20: =G20/G19-1 -> 0.022765857 | Y20: 46073 | Z20: =(R13*$Z$5+S13*$AA$5+T13*$AB$5+U13*$AC$5+V13*$AD$5) -> -0.0054058206 | AB20: TCS | AC20: 2.6025084e-05 | AD20: 3.2454481e-05 | AE20: 2.4770775e-05 | AF20: =VARP('Co-variance'!$U$7:$U$251) -> 0.00018455982 | AG20: 5.099957e-05
B21: 46063 | C21: 2453.6 | D21: 4269.1 | E21: 1406.5 | F21: 2984.6 | G21: 3675.8 | Q21: 46063 | R21: =C21/C20-1 -> -0.0037760364 | S21: =D21/D20-1 -> 0.0047068791 | T21: =E21/E20-1 -> 0.00028447479 | U21: =F21/F20-1 -> 0.025706234 | V21: =G21/G20-1 -> 0.00024490462 | Y21: 46072 | Z21: =(R14*$Z$5+S14*$AA$5+T14*$AB$5+U14*$AC$5+V14*$AD$5) -> -0.0058230344 | AB21: MAHM | AC21: 4.1381978e-05 | AD21: 5.8843218e-05 | AE21: 5.8906482e-05 | AF21: 5.099957e-05 | AG21: =VARP('Co-variance'!$V$7:$V$251) -> 0.00022483542
B22: 46062 | C22: 2435 | D22: 4257.8 | E22: 1396.3 | F22: 2948.2 | G22: 3609.6 | Q22: 46062 | R22: =C22/C21-1 -> -0.0075806978 | S22: =D22/D21-1 -> -0.0026469279 | T22: =E22/E21-1 -> -0.0072520441 | U22: =F22/F21-1 -> -0.012195939 | V22: =G22/G21-1 -> -0.018009685 | Y22: 46071 | Z22: =(R15*$Z$5+S15*$AA$5+T15*$AB$5+U15*$AC$5+V15*$AD$5) -> 0.014246436
B23: 46059 | C23: 2424.2 | D23: 4141 | E23: 1406.1 | F23: 2941.6 | G23: 3578 | Q23: 46059 | R23: =C23/C22-1 -> -0.0044353183 | S23: =D23/D22-1 -> -0.027432007 | T23: =E23/E22-1 -> 0.007018549 | U23: =F23/F22-1 -> -0.0022386541 | V23: =G23/G22-1 -> -0.0087544326 | Y23: 46070 | Z23: =(R16*$Z$5+S16*$AA$5+T16*$AB$5+U16*$AC$5+V16*$AD$5) -> -0.0010900424 | AB23: Data-> Data Analysis -> Covariance
B24: 46058 | C24: 2354.4 | D24: 4097.6 | E24: 1396.5 | F24: 2991.5 | G24: 3572 | Q24: 46058 | R24: =C24/C23-1 -> -0.028793004 | S24: =D24/D23-1 -> -0.01048056 | T24: =E24/E23-1 -> -0.0068273949 | U24: =F24/F23-1 -> 0.016963557 | V24: =G24/G23-1 -> -0.0016769145 | Y24: 46069 | Z24: =(R17*$Z$5+S17*$AA$5+T17*$AB$5+U17*$AC$5+V17*$AD$5) -> -0.0021622122
B25: 46057 | C25: 2371 | D25: 4144 | E25: 1408.4 | F25: 2999.1 | G25: 3574 | Q25: 46057 | R25: =C25/C24-1 -> 0.0070506286 | S25: =D25/D24-1 -> 0.011323702 | T25: =E25/E24-1 -> 0.0085213033 | U25: =F25/F24-1 -> 0.0025405315 | V25: =G25/G24-1 -> 0.00055991041 | Y25: 46066 | Z25: =(R18*$Z$5+S18*$AA$5+T18*$AB$5+U18*$AC$5+V18*$AD$5) -> -0.00075745244 | AB25: Standard deviation of Portfolio | AD25: {=SQRT(MMULT(MMULT(Z5:AD5,AC17:AG21),TRANSPOSE(Z5:AD5)))} -> 0.0075902673 | AE25: =_xlfn.FORMULATEXT(AD25) -> {=SQRT(MMULT(MMULT(Z5:AD5,AC17:AG21),TRANSPOSE(Z5:AD5)))}
B26: 46056 | C26: 2368.6 | D26: 4068.6 | E26: 1389.7 | F26: 3225.3 | G26: 3527.9 | Q26: 46056 | R26: =C26/C25-1 -> -0.0010122311 | S26: =D26/D25-1 -> -0.018194981 | T26: =E26/E25-1 -> -0.013277478 | U26: =F26/F25-1 -> 0.075422627 | V26: =G26/G25-1 -> -0.012898713 | Y26: 46065 | Z26: =(R19*$Z$5+S19*$AA$5+T19*$AB$5+U19*$AC$5+V19*$AD$5) -> 0.021835308
B27: 46055 | C27: 2357.3 | D27: 3953.2 | E27: 1352.8 | F27: 3169.6 | G27: 3463.2 | Q27: 46055 | R27: =C27/C26-1 -> -0.0047707507 | S27: =D27/D26-1 -> -0.028363565 | T27: =E27/E26-1 -> -0.026552493 | U27: =F27/F26-1 -> -0.017269711 | V27: =G27/G26-1 -> -0.018339522 | Y27: 46064 | Z27: =(R20*$Z$5+S20*$AA$5+T20*$AB$5+U20*$AC$5+V20*$AD$5) -> 0.010627227
B28: 46054 | C28: 2350.7 | D28: 3985.3 | E28: 1334.2 | F28: 3186.9 | G28: 3363.8 | Q28: 46054 | R28: =C28/C27-1 -> -0.0027998133 | S28: =D28/D27-1 -> 0.008120004 | T28: =E28/E27-1 -> -0.013749261 | U28: =F28/F27-1 -> 0.005458102 | V28: =G28/G27-1 -> -0.028701779 | Y28: 46063 | Z28: =(R21*$Z$5+S21*$AA$5+T21*$AB$5+U21*$AC$5+V21*$AD$5) -> 0.005861394
B29: 46052 | C29: 2373 | D29: 3977.4 | E29: 1355 | F29: 3123.9 | G29: 3431.8 | Q29: 46052 | R29: =C29/C28-1 -> 0.0094865359 | S29: =D29/D28-1 -> -0.0019822849 | T29: =E29/E28-1 -> 0.015589867 | U29: =F29/F28-1 -> -0.019768427 | V29: =G29/G28-1 -> 0.020215233 | Y29: 46062 | Z29: =(R22*$Z$5+S22*$AA$5+T22*$AB$5+U22*$AC$5+V22*$AD$5) -> -0.0082146062
B30: 46051 | C30: 2352.6 | D30: 3939.7 | E30: 1383.6 | F30: 3144.4 | G30: 3384.4 | Q30: 46051 | R30: =C30/C29-1 -> -0.008596713 | S30: =D30/D29-1 -> -0.0094785538 | T30: =E30/E29-1 -> 0.021107011 | U30: =F30/F29-1 -> 0.0065623099 | V30: =G30/G29-1 -> -0.013811994 | Y30: 46059 | Z30: =(R23*$Z$5+S23*$AA$5+T23*$AB$5+U23*$AC$5+V23*$AD$5) -> -0.0067409089
B31: 46050 | C31: 2378.4 | D31: 3975.2 | E31: 1367.7 | F31: 3200.1 | G31: 3449.2 | Q31: 46050 | R31: =C31/C30-1 -> 0.01096659 | S31: =D31/D30-1 -> 0.0090108384 | T31: =E31/E30-1 -> -0.011491761 | U31: =F31/F30-1 -> 0.017714031 | V31: =G31/G30-1 -> 0.019146673 | Y31: 46058 | Z31: =(R24*$Z$5+S24*$AA$5+T24*$AB$5+U24*$AC$5+V24*$AD$5) -> -0.0057622891
B32: 46049 | C32: 2400.9 | D32: 3997 | E32: 1361.4 | F32: 3158 | G32: 3393.5 | Q32: 46049 | R32: =C32/C31-1 -> 0.0094601413 | S32: =D32/D31-1 -> 0.0054840008 | T32: =E32/E31-1 -> -0.0046062733 | U32: =F32/F31-1 -> -0.013155839 | V32: =G32/G31-1 -> -0.016148672 | Y32: 46057 | Z32: =(R25*$Z$5+S25*$AA$5+T25*$AB$5+U25*$AC$5+V25*$AD$5) -> 0.007009008
B33: 46045 | C33: 2409.5 | D33: 4021.8 | E33: 1343.4 | F33: 3162.5 | G33: 3543.4 | Q33: 46045 | R33: =C33/C32-1 -> 0.0035819901 | S33: =D33/D32-1 -> 0.0062046535 | T33: =E33/E32-1 -> -0.013221684 | U33: =F33/F32-1 -> 0.0014249525 | V33: =G33/G32-1 -> 0.044172683 | Y33: 46056 | Z33: =(R26*$Z$5+S26*$AA$5+T26*$AB$5+U26*$AC$5+V26*$AD$5) -> 0.0051108308
B34: 46044 | C34: 2390.6 | D34: 4018.6 | E34: 1345.5 | F34: 3150.4 | G34: 3573.7 | Q34: 46044 | R34: =C34/C33-1 -> -0.007843951 | S34: =D34/D33-1 -> -0.00079566363 | T34: =E34/E33-1 -> 0.0015631979 | U34: =F34/F33-1 -> -0.003826087 | V34: =G34/G33-1 -> 0.0085511091 | Y34: 46055 | Z34: =(R27*$Z$5+S27*$AA$5+T27*$AB$5+U27*$AC$5+V27*$AD$5) -> -0.021060146
B35: 46043 | C35: 2368 | D35: 4079.2 | E35: 1349 | F35: 3122.6 | G35: 3553.3 | Q35: 46043 | R35: =C35/C34-1 -> -0.0094536936 | S35: =D35/D34-1 -> 0.015079879 | T35: =E35/E34-1 -> 0.0026012635 | U35: =F35/F34-1 -> -0.0088242763 | V35: =G35/G34-1 -> -0.0057083695 | Y35: 46054 | Z35: =(R28*$Z$5+S28*$AA$5+T28*$AB$5+U28*$AC$5+V28*$AD$5) -> -0.0042933067
B36: 46042 | C36: 2379.1 | D36: 4075.5 | E36: 1375.8 | F36: 3102.3 | G36: 3557.5 | Q36: 46042 | R36: =C36/C35-1 -> 0.0046875 | S36: =D36/D35-1 -> -0.0009070406 | T36: =E36/E35-1 -> 0.019866568 | U36: =F36/F35-1 -> -0.0065009928 | V36: =G36/G35-1 -> 0.0011819998 | Y36: 46052 | Z36: =(R29*$Z$5+S29*$AA$5+T29*$AB$5+U29*$AC$5+V29*$AD$5) -> 0.003672207
B37: 46041 | C37: 2413.9 | D37: 4144.1 | E37: 1380.6 | F37: 3163.6 | G37: 3657.4 | Q37: 46041 | R37: =C37/C36-1 -> 0.01462738 | S37: =D37/D36-1 -> 0.016832291 | T37: =E37/E36-1 -> 0.0034888792 | U37: =F37/F36-1 -> 0.019759533 | V37: =G37/G36-1 -> 0.028081518 | Y37: 46051 | Z37: =(R30*$Z$5+S30*$AA$5+T30*$AB$5+U30*$AC$5+V30*$AD$5) -> 0.0026042205
... B251: 45722 | C251: 2218.95 | D251: 3121.1 | E251: 1218.05 | F251: 3601.6 | G251: 2742.4 | Q251: 45722 | R251: =C251/C250-1 -> 0.0065319453 | S251: =D251/D250-1 -> 0.013558056 | T251: =E251/E250-1 -> 0.0028817257 | U251: =F251/F250-1 -> -0.0026583961 | V251: =G251/G250-1 -> 0.005333871 | Y251: 45734 | Z251: =(R244*$Z$5+S244*$AA$5+T244*$AB$5+U244*$AC$5+V244*$AD$5) -> 0.0030363084
Y252: 45733 | Z252: =(R245*$Z$5+S245*$AA$5+T245*$AB$5+U245*$AC$5+V245*$AD$5) -> -0.022802968
Y253: 45729 | Z253: =(R246*$Z$5+S246*$AA$5+T246*$AB$5+U246*$AC$5+V246*$AD$5) -> -0.0063468326
Y254: 45728 | Z254: =(R247*$Z$5+S247*$AA$5+T247*$AB$5+U247*$AC$5+V247*$AD$5) -> 0.00060975981
Y255: 45727 | Z255: =(R248*$Z$5+S248*$AA$5+T248*$AB$5+U248*$AC$5+V248*$AD$5) -> 0.0079193002
...
